Workbook

Sheet Import_UngaBunga
A1: ID | B1: Panel, XX, Case 1 | C1: Panel, XX, Case 2 | D1: Panel, XY, Case 1 | E1: Panel, XY, Case 2 | F1: Panel, YY, Case 1 | G1: Panel, YY, Case 2 | H1: Stringer, 1D, Case 1 | I1: Stringer, 1D, Case 2
A2: 1 | B2: 22.834734 | C2: 7.4184775 | D2: -35.701557 | E2: -154.15128 | F2: -66.018311 | G2: -24.847452
A3: 2 | B3: -81.947815 | C3: -26.965158 | D3: 39.505409 | E3: 155.9913 | F3: 25.816717 | G3: 8.4971561
A4: 3 | B4: 22.886993 | C4: 7.6230154 | D4: -42.99155 | E4: -156.55298 | F4: -64.292755 | G4: -18.027142
A5: 4 | B5: -92.855789 | C5: -30.056519 | D5: 41.965836 | E5: 154.20667 | F5: 21.546734 | G5: 7.10952
A6: 5 | B6: 28.454679 | C6: 9.3662701 | D6: -39.514854 | E6: -156.02853 | F6: -88.390434 | G6: -29.084965
A7: 6 | B7: -93.12764 | C7: -31.135933 | D7: 35.617687 | E7: 152.11722 | F7: 21.537046 | G7: 7.0629749
A8: 7 | B8: 23.219963 | C8: 7.6221585 | D8: -38.289162 | E8: -153.47383 | F8: -93.24659 | G8: -30.734118
A9: 8 | B9: -93.924248 | C9: -30.902781 | D9: 39.562 | E9: 156.20216 | F9: 25.086189 | G9: 8.2527046
A10: 9 | B10: 23.231916 | C10: 7.6619821 | D10: -39.556229 | E10: -153.89006 | F10: -93.216248 | G10: -30.619137
A11: 10 | B11: -93.187454 | C11: -30.662716 | D11: 40.711113 | E11: 154.2984 | F11: 23.774975 | G11: 7.8372531
A12: 11 | B12: -93.290771 | C12: -30.694557 | D12: 39.571175 | E12: 156.23773 | F12: 23.99432 | G12: 7.8926597
A13: 12 | B13: -93.187889 | C13: -30.663221 | D13: 37.148136 | E13: 153.12602 | F13: 23.769667 | G13: 7.8104858
... A31: 30 | B31: 22.18527 | C31: 7.193449 | D31: -34.603394 | E31: -154.30954 | F31: -69.829636 | G31: -26.051102
A32: 31
A33: 32
A34: 33
A35: 34
A36: 35
A37: 36
A38: 37 | H38: -84.510918 | I38: -26.748228
A39: 38 | H39: -76.450066 | I39: -25.15695
A40: 39 | H40: -85.092255 | I40: -29.045668
A41: 40 | H41: -85.12233 | I41: -28.03298
A42: 41 | H42: -88.499741 | I42: -29.122883
A43: 42 | H43: -85.107826 | I43: -27.976954
A44: 43 | H44: -73.137466 | I44: -24.11269
A45: 44 | H45: -73.50914 | I45: -24.182793
A46: 45 | H46: -73.113197 | I46: -24.012451
A47: 46 | H47: -83.890106 | I47: -27.580795
A48: 47 | H48: -84.565605 | I48: -27.824999
A49: 48 | H49: -83.90313 | I49: -27.630136
... A64: 63 | H64: -69.415634 | I64: -21.853281
A65: 65

Sheet Import
A1: ID | B1: Panel, XX, Case 1 | C1: Panel, XX, Case 2 | D1: Panel, XY, Case 1 | E1: Panel, XY, Case 2 | F1: Panel, YY, Case 1 | G1: Panel, YY, Case 2 | H1: Stringer, 1D, Case 1 | I1: Stringer, 1D, Case 2
A2: 1 | B2: -20 | C2: =MIN(Import_UngaBunga!C2,Import_UngaBunga!G2) -> -24.847452 | D2: =ABS(Import_UngaBunga!D2) -> 35.701557 | E2: =ABS(Import_UngaBunga!E2) -> 154.15128 | F2: =MAX(Import_UngaBunga!B2,Import_UngaBunga!F2) -> 22.834734 | G2: =MAX(Import_UngaBunga!C2,Import_UngaBunga!G2) -> 7.4184775
A3: 2 | B3: =MIN(Import_UngaBunga!B3,Import_UngaBunga!F3) -> -81.947815 | C3: =MIN(Import_UngaBunga!C3,Import_UngaBunga!G3) -> -26.965158 | D3: =ABS(Import_UngaBunga!D3) -> 39.505409 | E3: =ABS(Import_UngaBunga!E3) -> 155.9913 | F3: =MAX(Import_UngaBunga!B3,Import_UngaBunga!F3) -> 25.816717 | G3: =MAX(Import_UngaBunga!C3,Import_UngaBunga!G3) -> 8.4971561
A4: 3 | B4: =MIN(Import_UngaBunga!B4,Import_UngaBunga!F4) -> -64.292755 | C4: =MIN(Import_UngaBunga!C4,Import_UngaBunga!G4) -> -18.027142 | D4: =ABS(Import_UngaBunga!D4) -> 42.99155 | E4: =ABS(Import_UngaBunga!E4) -> 156.55298 | F4: =MAX(Import_UngaBunga!B4,Import_UngaBunga!F4) -> 22.886993 | G4: =MAX(Import_UngaBunga!C4,Import_UngaBunga!G4) -> 7.6230154
A5: 4 | B5: =MIN(Import_UngaBunga!B5,Import_UngaBunga!F5) -> -92.855789 | C5: =MIN(Import_UngaBunga!C5,Import_UngaBunga!G5) -> -30.056519 | D5: =ABS(Import_UngaBunga!D5) -> 41.965836 | E5: =ABS(Import_UngaBunga!E5) -> 154.20667 | F5: =MAX(Import_UngaBunga!B5,Import_UngaBunga!F5) -> 21.546734 | G5: =MAX(Import_UngaBunga!C5,Import_UngaBunga!G5) -> 7.10952
A6: 5 | B6: =MIN(Import_UngaBunga!B6,Import_UngaBunga!F6) -> -88.390434 | C6: =MIN(Import_UngaBunga!C6,Import_UngaBunga!G6) -> -29.084965 | D6: =ABS(Import_UngaBunga!D6) -> 39.514854 | E6: =ABS(Import_UngaBunga!E6) -> 156.02853 | F6: =MAX(Import_UngaBunga!B6,Import_UngaBunga!F6) -> 28.454679 | G6: =MAX(Import_UngaBunga!C6,Import_UngaBunga!G6) -> 9.3662701
A7: 6 | B7: =MIN(Import_UngaBunga!B7,Import_UngaBunga!F7) -> -93.12764 | C7: =MIN(Import_UngaBunga!C7,Import_UngaBunga!G7) -> -31.135933 | D7: =ABS(Import_UngaBunga!D7) -> 35.617687 | E7: =ABS(Import_UngaBunga!E7) -> 152.11722 | F7: =MAX(Import_UngaBunga!B7,Import_UngaBunga!F7) -> 21.537046 | G7: =MAX(Import_UngaBunga!C7,Import_UngaBunga!G7) -> 7.0629749
A8: 7 | B8: =MIN(Import_UngaBunga!B8,Import_UngaBunga!F8) -> -93.24659 | C8: =MIN(Import_UngaBunga!C8,Import_UngaBunga!G8) -> -30.734118 | D8: =ABS(Import_UngaBunga!D8) -> 38.289162 | E8: =ABS(Import_UngaBunga!E8) -> 153.47383 | F8: =MAX(Import_UngaBunga!B8,Import_UngaBunga!F8) -> 23.219963 | G8: =MAX(Import_UngaBunga!C8,Import_UngaBunga!G8) -> 7.6221585
A9: 8 | B9: =MIN(Import_UngaBunga!B9,Import_UngaBunga!F9) -> -93.924248 | C9: =MIN(Import_UngaBunga!C9,Import_UngaBunga!G9) -> -30.902781 | D9: =ABS(Import_UngaBunga!D9) -> 39.562 | E9: =ABS(Import_UngaBunga!E9) -> 156.20216 | F9: =MAX(Import_UngaBunga!B9,Import_UngaBunga!F9) -> 25.086189 | G9: =MAX(Import_UngaBunga!C9,Import_UngaBunga!G9) -> 8.2527046
A10: 9 | B10: =MIN(Import_UngaBunga!B10,Import_UngaBunga!F10) -> -93.216248 | C10: =MIN(Import_UngaBunga!C10,Import_UngaBunga!G10) -> -30.619137 | D10: =ABS(Import_UngaBunga!D10) -> 39.556229 | E10: =ABS(Import_UngaBunga!E10) -> 153.89006 | F10: =MAX(Import_UngaBunga!B10,Import_UngaBunga!F10) -> 23.231916 | G10: =MAX(Import_UngaBunga!C10,Import_UngaBunga!G10) -> 7.6619821
A11: 10 | B11: =MIN(Import_UngaBunga!B11,Import_UngaBunga!F11) -> -93.187454 | C11: =MIN(Import_UngaBunga!C11,Import_UngaBunga!G11) -> -30.662716 | D11: =ABS(Import_UngaBunga!D11) -> 40.711113 | E11: =ABS(Import_UngaBunga!E11) -> 154.2984 | F11: =MAX(Import_UngaBunga!B11,Import_UngaBunga!F11) -> 23.774975 | G11: =MAX(Import_UngaBunga!C11,Import_UngaBunga!G11) -> 7.8372531
A12: 11 | B12: =MIN(Import_UngaBunga!B12,Import_UngaBunga!F12) -> -93.290771 | C12: =MIN(Import_UngaBunga!C12,Import_UngaBunga!G12) -> -30.694557 | D12: =ABS(Import_UngaBunga!D12) -> 39.571175 | E12: =ABS(Import_UngaBunga!E12) -> 156.23773 | F12: =MAX(Import_UngaBunga!B12,Import_UngaBunga!F12) -> 23.99432 | G12: =MAX(Import_UngaBunga!C12,Import_UngaBunga!G12) -> 7.8926597
A13: 12 | B13: =MIN(Import_UngaBunga!B13,Import_UngaBunga!F13) -> -93.187889 | C13: =MIN(Import_UngaBunga!C13,Import_UngaBunga!G13) -> -30.663221 | D13: =ABS(Import_UngaBunga!D13) -> 37.148136 | E13: =ABS(Import_UngaBunga!E13) -> 153.12602 | F13: =MAX(Import_UngaBunga!B13,Import_UngaBunga!F13) -> 23.769667 | G13: =MAX(Import_UngaBunga!C13,Import_UngaBunga!G13) -> 7.8104858
A14: 13 | B14: =MIN(Import_UngaBunga!B14,Import_UngaBunga!F14) -> -92.898605 | C14: =MIN(Import_UngaBunga!C14,Import_UngaBunga!G14) -> -30.570362 | D14: =ABS(Import_UngaBunga!D14) -> 37.408363 | E14: =ABS(Import_UngaBunga!E14) -> 153.20596 | F14: =MAX(Import_UngaBunga!B14,Import_UngaBunga!F14) -> 23.865223 | G14: =MAX(Import_UngaBunga!C14,Import_UngaBunga!G14) -> 7.8355255
... A31: 30 | B31: =MIN(Import_UngaBunga!B31,Import_UngaBunga!F31) -> -69.829636 | C31: =MIN(Import_UngaBunga!C31,Import_UngaBunga!G31) -> -26.051102 | D31: =ABS(Import_UngaBunga!D31) -> 34.603394 | E31: =ABS(Import_UngaBunga!E31) -> 154.30954 | F31: =MAX(Import_UngaBunga!B31,Import_UngaBunga!F31) -> 22.18527 | G31: =MAX(Import_UngaBunga!C31,Import_UngaBunga!G31) -> 7.193449
A32: 31
A33: 32
A34: 33
A35: 34
A36: 35
A37: 36
A38: 37 | H38: -84.510918 | I38: -26.748228
A39: 38 | H39: -76.450066 | I39: -25.15695
A40: 39 | H40: -85.092255 | I40: -29.045668
A41: 40 | H41: -85.12233 | I41: -28.03298
A42: 41 | H42: -88.499741 | I42: -29.122883
A43: 42 | H43: -85.107826 | I43: -27.976954
A44: 43 | H44: -73.137466 | I44: -24.11269
A45: 44 | H45: -73.50914 | I45: -24.182793
A46: 45 | H46: -73.113197 | I46: -24.012451
A47: 46 | H47: -83.890106 | I47: -27.580795
A48: 47 | H48: -84.565605 | I48: -27.824999
A49: 48 | H49: -83.90313 | I49: -27.630136
... A64: 63 | H64: -69.415634 | I64: -21.853281
A65: 65

Sheet Results_d
A1: Ultimate Strength | C1: Van Mises Panel, Case 1 | D1: Van Mises Panel, Case 2 | E1: Axial Stringer, Case 1 | F1: Axial Stringer, Case 2 | H1: RF Strength, Loadcase 1 | I1: RF Strength, Loadcase 2
A2: 531.78 | B2: =Import!A2 -> 1 | C2: =SQRT(Import!B2^2+Import!F2^2-Import!B2*Import!F2+3*Import!D2^2) -> 72.12436 | D2: =SQRT(Import!C2^2+Import!G2^2-Import!C2*Import!G2+3*Import!E2^2) -> 268.59748 | E2: =ABS(Import!H2) -> 0 | F2: =ABS(Import!I2) -> 0 | H2: =IF(C2<>0,$A$2/(1.5*C2),IF(E2<>0,$A$2/(1.5*E2),"NaN")) -> 4.9153989 | I2: =IF(D2<>0,$A$2/(1.5*D2),IF(F2<>0,$A$2/(1.5*F2),"NaN")) -> 1.3198932
B3: =Import!A3 -> 2 | C3: =SQRT(Import!B3^2+Import!F3^2-Import!B3*Import!F3+3*Import!D3^2) -> 119.07814 | D3: =SQRT(Import!C3^2+Import!G3^2-Import!C3*Import!G3+3*Import!E3^2) -> 272.08144 | E3: =ABS(Import!H3) -> 0 | F3: =ABS(Import!I3) -> 0 | H3: =IF(C3<>0,$A$2/(1.5*C3),IF(E3<>0,$A$2/(1.5*E3),"NaN")) -> 2.9772048 | I3: =IF(D3<>0,$A$2/(1.5*D3),IF(F3<>0,$A$2/(1.5*F3),"NaN")) -> 1.3029922
B4: =Import!A4 -> 3 | C4: =SQRT(Import!B4^2+Import!F4^2-Import!B4*Import!F4+3*Import!D4^2) -> 108.04472 | D4: =SQRT(Import!C4^2+Import!G4^2-Import!C4*Import!G4+3*Import!E4^2) -> 272.11581 | E4: =ABS(Import!H4) -> 0 | F4: =ABS(Import!I4) -> 0 | H4: =IF(C4<>0,$A$2/(1.5*C4),IF(E4<>0,$A$2/(1.5*E4),"NaN")) -> 3.281234 | I4: =IF(D4<>0,$A$2/(1.5*D4),IF(F4<>0,$A$2/(1.5*F4),"NaN")) -> 1.3028276
B5: =Import!A5 -> 4 | C5: =SQRT(Import!B5^2+Import!F5^2-Import!B5*Import!F5+3*Import!D5^2) -> 127.94762 | D5: =SQRT(Import!C5^2+Import!G5^2-Import!C5*Import!G5+3*Import!E5^2) -> 269.27071 | E5: =ABS(Import!H5) -> 0 | F5: =ABS(Import!I5) -> 0 | H5: =IF(C5<>0,$A$2/(1.5*C5),IF(E5<>0,$A$2/(1.5*E5),"NaN")) -> 2.7708215 | I5: =IF(D5<>0,$A$2/(1.5*D5),IF(F5<>0,$A$2/(1.5*F5),"NaN")) -> 1.3165933
B6: =Import!A6 -> 5 | C6: =SQRT(Import!B6^2+Import!F6^2-Import!B6*Import!F6+3*Import!D6^2) -> 125.78525 | D6: =SQRT(Import!C6^2+Import!G6^2-Import!C6*Import!G6+3*Import!E6^2) -> 272.47163 | E6: =ABS(Import!H6) -> 0 | F6: =ABS(Import!I6) -> 0 | H6: =IF(C6<>0,$A$2/(1.5*C6),IF(E6<>0,$A$2/(1.5*E6),"NaN")) -> 2.8184544 | I6: =IF(D6<>0,$A$2/(1.5*D6),IF(F6<>0,$A$2/(1.5*F6),"NaN")) -> 1.3011263
B7: =Import!A7 -> 6 | C7: =SQRT(Import!B7^2+Import!F7^2-Import!B7*Import!F7+3*Import!D7^2) -> 122.26265 | D7: =SQRT(Import!C7^2+Import!G7^2-Import!C7*Import!G7+3*Import!E7^2) -> 265.81608 | E7: =ABS(Import!H7) -> 0 | F7: =ABS(Import!I7) -> 0 | H7: =IF(C7<>0,$A$2/(1.5*C7),IF(E7<>0,$A$2/(1.5*E7),"NaN")) -> 2.8996591 | I7: =IF(D7<>0,$A$2/(1.5*D7),IF(F7<>0,$A$2/(1.5*F7),"NaN")) -> 1.3337041
B8: =Import!A8 -> 7 | C8: =SQRT(Import!B8^2+Import!F8^2-Import!B8*Import!F8+3*Import!D8^2) -> 125.68793 | D8: =SQRT(Import!C8^2+Import!G8^2-Import!C8*Import!G8+3*Import!E8^2) -> 268.141 | E8: =ABS(Import!H8) -> 0 | F8: =ABS(Import!I8) -> 0 | H8: =IF(C8<>0,$A$2/(1.5*C8),IF(E8<>0,$A$2/(1.5*E8),"NaN")) -> 2.8206368 | I8: =IF(D8<>0,$A$2/(1.5*D8),IF(F8<>0,$A$2/(1.5*F8),"NaN")) -> 1.3221402
B9: =Import!A9 -> 8 | C9: =SQRT(Import!B9^2+Import!F9^2-Import!B9*Import!F9+3*Import!D9^2) -> 128.46298 | D9: =SQRT(Import!C9^2+Import!G9^2-Import!C9*Import!G9+3*Import!E9^2) -> 272.90194 | E9: =ABS(Import!H9) -> 0 | F9: =ABS(Import!I9) -> 0 | H9: =IF(C9<>0,$A$2/(1.5*C9),IF(E9<>0,$A$2/(1.5*E9),"NaN")) -> 2.7597055 | I9: =IF(D9<>0,$A$2/(1.5*D9),IF(F9<>0,$A$2/(1.5*F9),"NaN")) -> 1.2990747
B10: =Import!A10 -> 9 | C10: =SQRT(Import!B10^2+Import!F10^2-Import!B10*Import!F10+3*Import!D10^2) -> 126.84112 | D10: =SQRT(Import!C10^2+Import!G10^2-Import!C10*Import!G10+3*Import!E10^2) -> 268.84437 | E10: =ABS(Import!H10) -> 0 | F10: =ABS(Import!I10) -> 0 | H10: =IF(C10<>0,$A$2/(1.5*C10),IF(E10<>0,$A$2/(1.5*E10),"NaN")) -> 2.7949928 | I10: =IF(D10<>0,$A$2/(1.5*D10),IF(F10<>0,$A$2/(1.5*F10),"NaN")) -> 1.3186812
B11: =Import!A11 -> 10 | C11: =SQRT(Import!B11^2+Import!F11^2-Import!B11*Import!F11+3*Import!D11^2) -> 128.20634 | D11: =SQRT(Import!C11^2+Import!G11^2-Import!C11*Import!G11+3*Import!E11^2) -> 269.56618 | E11: =ABS(Import!H11) -> 0 | F11: =ABS(Import!I11) -> 0 | H11: =IF(C11<>0,$A$2/(1.5*C11),IF(E11<>0,$A$2/(1.5*E11),"NaN")) -> 2.7652299 | I11: =IF(D11<>0,$A$2/(1.5*D11),IF(F11<>0,$A$2/(1.5*F11),"NaN")) -> 1.3151501
B12: =Import!A12 -> 11 | C12: =SQRT(Import!B12^2+Import!F12^2-Import!B12*Import!F12+3*Import!D12^2) -> 127.33804 | D12: =SQRT(Import!C12^2+Import!G12^2-Import!C12*Import!G12+3*Import!E12^2) -> 272.90547 | E12: =ABS(Import!H12) -> 0 | F12: =ABS(Import!I12) -> 0 | H12: =IF(C12<>0,$A$2/(1.5*C12),IF(E12<>0,$A$2/(1.5*E12),"NaN")) -> 2.7840855 | I12: =IF(D12<>0,$A$2/(1.5*D12),IF(F12<>0,$A$2/(1.5*F12),"NaN")) -> 1.2990579
B13: =Import!A13 -> 12 | C13: =SQRT(Import!B13^2+Import!F13^2-Import!B13*Import!F13+3*Import!D13^2) -> 124.91588 | D13: =SQRT(Import!C13^2+Import!G13^2-Import!C13*Import!G13+3*Import!E13^2) -> 267.55087 | E13: =ABS(Import!H13) -> 0 | F13: =ABS(Import!I13) -> 0 | H13: =IF(C13<>0,$A$2/(1.5*C13),IF(E13<>0,$A$2/(1.5*E13),"NaN")) -> 2.8380699 | I13: =IF(D13<>0,$A$2/(1.5*D13),IF(F13<>0,$A$2/(1.5*F13),"NaN")) -> 1.3250564
B14: =Import!A14 -> 13 | C14: =SQRT(Import!B14^2+Import!F14^2-Import!B14*Import!F14+3*Import!D14^2) -> 124.9596 | D14: =SQRT(Import!C14^2+Import!G14^2-Import!C14*Import!G14+3*Import!E14^2) -> 267.67831 | E14: =ABS(Import!H14) -> 0 | F14: =ABS(Import!I14) -> 0 | H14: =IF(C14<>0,$A$2/(1.5*C14),IF(E14<>0,$A$2/(1.5*E14),"NaN")) -> 2.8370769 | I14: =IF(D14<>0,$A$2/(1.5*D14),IF(F14<>0,$A$2/(1.5*F14),"NaN")) -> 1.3244256
... B31: =Import!A31 -> 30 | C31: =SQRT(Import!B31^2+Import!F31^2-Import!B31*Import!F31+3*Import!D31^2) -> 102.51701 | D31: =SQRT(Import!C31^2+Import!G31^2-Import!C31*Import!G31+3*Import!E31^2) -> 268.98347 | E31: =ABS(Import!H31) -> 0 | F31: =ABS(Import!I31) -> 0 | H31: =IF(C31<>0,$A$2/(1.5*C31),IF(E31<>0,$A$2/(1.5*E31),"NaN")) -> 3.4581577 | I31: =IF(D31<>0,$A$2/(1.5*D31),IF(F31<>0,$A$2/(1.5*F31),"NaN")) -> 1.3179992
B32: =Import!A32 -> 31 | C32: =SQRT(Import!B32^2 + Import!F32^2 - Import!B32*F32 + 3*Import!D32^2) -> 0 | D32: =SQRT(Import!C32^2 + Import!G32^2 - Import!C32*Import!G32 + 3*Import!E32^2) -> 0 | E32: =ABS(Import!H32) -> 0 | F32: =ABS(Import!I32) -> 0 | H32: =IF(C32<>0,$A$2/(1.5*C32),IF(E32<>0,$A$2/(1.5*E32),"NaN")) -> NaN | I32: =IF(D32<>0,$A$2/(1.5*D32),IF(F32<>0,$A$2/(1.5*F32),"NaN")) -> NaN
B33: =Import!A33 -> 32 | C33: =SQRT(Import!B33^2 + Import!F33^2 - Import!B33*F33 + 3*Import!D33^2) -> 0 | D33: =SQRT(Import!C33^2 + Import!G33^2 - Import!C33*Import!G33 + 3*Import!E33^2) -> 0 | E33: =ABS(Import!H33) -> 0 | F33: =ABS(Import!I33) -> 0 | H33: =IF(C33<>0,$A$2/(1.5*C33),IF(E33<>0,$A$2/(1.5*E33),"NaN")) -> NaN | I33: =IF(D33<>0,$A$2/(1.5*D33),IF(F33<>0,$A$2/(1.5*F33),"NaN")) -> NaN
B34: =Import!A34 -> 33 | C34: =SQRT(Import!B34^2 + Import!F34^2 - Import!B34*F34 + 3*Import!D34^2) -> 0 | D34: =SQRT(Import!C34^2 + Import!G34^2 - Import!C34*Import!G34 + 3*Import!E34^2) -> 0 | E34: =ABS(Import!H34) -> 0 | F34: =ABS(Import!I34) -> 0 | H34: =IF(C34<>0,$A$2/(1.5*C34),IF(E34<>0,$A$2/(1.5*E34),"NaN")) -> NaN | I34: =IF(D34<>0,$A$2/(1.5*D34),IF(F34<>0,$A$2/(1.5*F34),"NaN")) -> NaN
B35: =Import!A35 -> 34 | C35: =SQRT(Import!B35^2 + Import!F35^2 - Import!B35*F35 + 3*Import!D35^2) -> 0 | D35: =SQRT(Import!C35^2 + Import!G35^2 - Import!C35*Import!G35 + 3*Import!E35^2) -> 0 | E35: =ABS(Import!H35) -> 0 | F35: =ABS(Import!I35) -> 0 | H35: =IF(C35<>0,$A$2/(1.5*C35),IF(E35<>0,$A$2/(1.5*E35),"NaN")) -> NaN | I35: =IF(D35<>0,$A$2/(1.5*D35),IF(F35<>0,$A$2/(1.5*F35),"NaN")) -> NaN
B36: =Import!A36 -> 35 | C36: =SQRT(Import!B36^2 + Import!F36^2 - Import!B36*F36 + 3*Import!D36^2) -> 0 | D36: =SQRT(Import!C36^2 + Import!G36^2 - Import!C36*Import!G36 + 3*Import!E36^2) -> 0 | E36: =ABS(Import!H36) -> 0 | F36: =ABS(Import!I36) -> 0 | H36: =IF(C36<>0,$A$2/(1.5*C36),IF(E36<>0,$A$2/(1.5*E36),"NaN")) -> NaN | I36: =IF(D36<>0,$A$2/(1.5*D36),IF(F36<>0,$A$2/(1.5*F36),"NaN")) -> NaN
B37: =Import!A37 -> 36 | C37: =SQRT(Import!B37^2 + Import!F37^2 - Import!B37*F37 + 3*Import!D37^2) -> 0 | D37: =SQRT(Import!C37^2 + Import!G37^2 - Import!C37*Import!G37 + 3*Import!E37^2) -> 0 | E37: =ABS(Import!H37) -> 0 | F37: =ABS(Import!I37) -> 0 | H37: =IF(C37<>0,$A$2/(1.5*C37),IF(E37<>0,$A$2/(1.5*E37),"NaN")) -> NaN | I37: =IF(D37<>0,$A$2/(1.5*D37),IF(F37<>0,$A$2/(1.5*F37),"NaN")) -> NaN
B38: =Import!A38 -> 37 | C38: =SQRT(Import!B38^2 + Import!F38^2 - Import!B38*F38 + 3*Import!D38^2) -> 0 | D38: =SQRT(Import!C38^2 + Import!G38^2 - Import!C38*Import!G38 + 3*Import!E38^2) -> 0 | E38: =ABS(Import!H38) -> 84.510918 | F38: =ABS(Import!I38) -> 26.748228 | H38: =IF(C38<>0,$A$2/(1.5*C38),IF(E38<>0,$A$2/(1.5*E38),"NaN")) -> 4.194961 | I38: =IF(D38<>0,$A$2/(1.5*D38),IF(F38<>0,$A$2/(1.5*F38),"NaN")) -> 13.253962
B39: =Import!A39 -> 38 | C39: =SQRT(Import!B39^2 + Import!F39^2 - Import!B39*F39 + 3*Import!D39^2) -> 0 | D39: =SQRT(Import!C39^2 + Import!G39^2 - Import!C39*Import!G39 + 3*Import!E39^2) -> 0 | E39: =ABS(Import!H39) -> 76.450066 | F39: =ABS(Import!I39) -> 25.15695 | H39: =IF(C39<>0,$A$2/(1.5*C39),IF(E39<>0,$A$2/(1.5*E39),"NaN")) -> 4.6372753 | I39: =IF(D39<>0,$A$2/(1.5*D39),IF(F39<>0,$A$2/(1.5*F39),"NaN")) -> 14.092328
B40: =Import!A40 -> 39 | C40: =SQRT(Import!B40^2 + Import!F40^2 - Import!B40*F40 + 3*Import!D40^2) -> 0 | D40: =SQRT(Import!C40^2 + Import!G40^2 - Import!C40*Import!G40 + 3*Import!E40^2) -> 0 | E40: =ABS(Import!H40) -> 85.092255 | F40: =ABS(Import!I40) -> 29.045668 | H40: =IF(C40<>0,$A$2/(1.5*C40),IF(E40<>0,$A$2/(1.5*E40),"NaN")) -> 4.1663016 | I40: =IF(D40<>0,$A$2/(1.5*D40),IF(F40<>0,$A$2/(1.5*F40),"NaN")) -> 12.205607
B41: =Import!A41 -> 40 | C41: =SQRT(Import!B41^2 + Import!F41^2 - Import!B41*F41 + 3*Import!D41^2) -> 0 | D41: =SQRT(Import!C41^2 + Import!G41^2 - Import!C41*Import!G41 + 3*Import!E41^2) -> 0 | E41: =ABS(Import!H41) -> 85.12233 | F41: =ABS(Import!I41) -> 28.03298 | H41: =IF(C41<>0,$A$2/(1.5*C41),IF(E41<>0,$A$2/(1.5*E41),"NaN")) -> 4.1648296 | I41: =IF(D41<>0,$A$2/(1.5*D41),IF(F41<>0,$A$2/(1.5*F41),"NaN")) -> 12.646533
B42: =Import!A42 -> 41 | C42: =SQRT(Import!B42^2 + Import!F42^2 - Import!B42*F42 + 3*Import!D42^2) -> 0 | D42: =SQRT(Import!C42^2 + Import!G42^2 - Import!C42*Import!G42 + 3*Import!E42^2) -> 0 | E42: =ABS(Import!H42) -> 88.499741 | F42: =ABS(Import!I42) -> 29.122883 | H42: =IF(C42<>0,$A$2/(1.5*C42),IF(E42<>0,$A$2/(1.5*E42),"NaN")) -> 4.0058874 | I42: =IF(D42<>0,$A$2/(1.5*D42),IF(F42<>0,$A$2/(1.5*F42),"NaN")) -> 12.173245
B43: =Import!A43 -> 42 | C43: =SQRT(Import!B43^2 + Import!F43^2 - Import!B43*F43 + 3*Import!D43^2) -> 0 | D43: =SQRT(Import!C43^2 + Import!G43^2 - Import!C43*Import!G43 + 3*Import!E43^2) -> 0 | E43: =ABS(Import!H43) -> 85.107826 | F43: =ABS(Import!I43) -> 27.976954 | H43: =IF(C43<>0,$A$2/(1.5*C43),IF(E43<>0,$A$2/(1.5*E43),"NaN")) -> 4.1655394 | I43: =IF(D43<>0,$A$2/(1.5*D43),IF(F43<>0,$A$2/(1.5*F43),"NaN")) -> 12.671859
... B64: =Import!A64 -> 63 | C64: =SQRT(Import!B64^2 + Import!F64^2 - Import!B64*F64 + 3*Import!D64^2) -> 0 | D64: =SQRT(Import!C64^2 + Import!G64^2 - Import!C64*Import!G64 + 3*Import!E64^2) -> 0 | E64: =ABS(Import!H64) -> 69.415634 | F64: =ABS(Import!I64) -> 21.853281 | H64: =IF(C64<>0,$A$2/(1.5*C64),IF(E64<>0,$A$2/(1.5*E64),"NaN")) -> 5.1072068 | I64: =IF(D64<>0,$A$2/(1.5*D64),IF(F64<>0,$A$2/(1.5*F64),"NaN")) -> 16.222736

Sheet Volume
A1: T-section | D1: Omega-Section | G1: t_thickness_skin | H1: 3.9 | K1: T-section | N1: Omega-Section
A2: Number | B2: 4 | D2: Number | E2: 5 | G2: a | H2: 600 | K2: Number | L2: 4 | N2: Number | O2: 5
A3: DIM1 | B3: 65 | D3: DIM1 | E3: 28 | G3: b | H3: 200 | K3: DIM1 | L3: 65 | N3: DIM1 | O3: 28
A4: DIM2 | B4: 42 | D4: DIM2 | E4: 2.4 | K4: DIM2 | L4: 42 | N4: DIM2 | O4: 2.4
A5: DIM3 | B5: 3 | D5: DIM3 | E5: 20 | K5: DIM3 | L5: 3 | N5: DIM3 | O5: 20
A6: DIM4 | B6: 20 | D6: DIM4 | E6: 15 | K6: DIM4 | L6: 2.1 | N6: DIM4 | O6: 15
A32: Volume skin | B32: =H1*H2*H3 -> 468000
A34: Area T_stringer | B34: =B3*B5 + (B4-B5)*B6 -> 975
A35: Volume T-stringer | B35: =B34*H2 -> 585000
A37: Area Omega-Stringer | B37: =2*E6*E4 + 2*E3*E4 + (E5-2*E4) * E4 -> 242.88
A38: Volume T-stringer | B38: =B37*H2 -> 145728
A40: Density | B40: 2.7e-09
A42: Mass_computed | B42: =B40*(10*B32+B35*4 + B38*5) * 10^3 -> 20.921328
A43: Mass_high_precision | B43: =B40*(SUM('Results_e,f'!B2:B31)+SUM('Results_e,f'!B38:B64)) * 10^3 -> 16.397641

Sheet Results_e,f
A1: Element ID | B1: Volume | C1: Panel ID | D1: Combined Volume | E1: XX, Case 1, Average | F1: XX, Case 2, Average | G1: XY, Case 1, Average | H1: XY, Case 2, Average | I1: YY, Case 1, Average | J1: YY, Case 2, Average | L1: volume | M1: xx,case1 | N1: xx,case2 | O1: stringer axial, case1 | P1: stringer axial, case2
A2: =Import!A2 -> 1 | B2: 156002.72 | C2: 1 | D2: =SUM(B2:B4) -> 468000.28 | E2: =SUMPRODUCT('Results_e,f'!$B2:$B4,Import!B2:B4)/$D2 -> -55.413273 | F2: =SUMPRODUCT('Results_e,f'!$B2:$B4,Import!C2:C4)/$D2 -> -23.279955 | G2: =SUMPRODUCT('Results_e,f'!$B2:$B4,Import!D2:D4)/$D2 -> 39.399465 | H2: =SUMPRODUCT('Results_e,f'!$B2:$B4,Import!E2:E4)/$D2 -> 155.56517 | I2: =SUMPRODUCT('Results_e,f'!$B2:$B4,Import!F2:F4)/$D2 -> 23.846148 | J2: =SUMPRODUCT('Results_e,f'!$B2:$B4,Import!G2:G4)/$D2 -> 7.8462151 | K2: 1 | L2: {=_xlfn._xlws.FILTER(D2:D31,D2:D31<>"")} -> 468000.28 | M2: {=_xlfn._xlws.FILTER(E2:E31,E2:E31<>"")} -> -55.413273 | N2: {=_xlfn._xlws.FILTER(F2:F31,F2:F31<>"")} -> -23.279955
A3: =Import!A3 -> 2 | B3: 156000.06 | K3: 2 | L3: 468000.28 | M3: -91.457956 | N3: -30.092478
A4: =Import!A4 -> 3 | B4: 155997.5 | K4: 3 | L4: 467995.54 | M4: -93.46236 | N4: -30.752011
A5: =Import!A5 -> 4 | B5: 155997.5 | C5: 2 | D5: =SUM(B5:B7) -> 468000.28 | E5: =SUMPRODUCT('Results_e,f'!$B5:$B7,Import!B5:B7)/$D5 -> -91.457956 | F5: =SUMPRODUCT('Results_e,f'!$B5:$B7,Import!C5:C7)/$D5 -> -30.092478 | G5: =SUMPRODUCT('Results_e,f'!$B5:$B7,Import!D5:D7)/$D5 -> 39.032757 | H5: =SUMPRODUCT('Results_e,f'!$B5:$B7,Import!E5:E7)/$D5 -> 154.11746 | I5: =SUMPRODUCT('Results_e,f'!$B5:$B7,Import!F5:F7)/$D5 -> 23.846153 | J5: =SUMPRODUCT('Results_e,f'!$B5:$B7,Import!G5:G7)/$D5 -> 7.8462545 | K5: 4 | L5: 468003.11 | M5: -93.222038 | N5: -30.673498
A6: =Import!A6 -> 5 | B6: 156000.06 | K6: 5 | L6: 468000.7 | M6: -92.821111 | N6: -30.54099
A7: =Import!A7 -> 6 | B7: 156002.73 | K7: 6 | L7: 467998.75 | M7: -92.705719 | N7: -30.503162
A8: =Import!A8 -> 7 | B8: 155999.83 | C8: 3 | D8: =SUM(B8:B10) -> 467995.54 | E8: =SUMPRODUCT('Results_e,f'!$B8:$B10,Import!B8:B10)/$D8 -> -93.46236 | F8: =SUMPRODUCT('Results_e,f'!$B8:$B10,Import!C8:C10)/$D8 -> -30.752011 | G8: =SUMPRODUCT('Results_e,f'!$B8:$B10,Import!D8:D10)/$D8 -> 39.135793 | H8: =SUMPRODUCT('Results_e,f'!$B8:$B10,Import!E8:E10)/$D8 -> 154.52201 | I8: =SUMPRODUCT('Results_e,f'!$B8:$B10,Import!F8:F10)/$D8 -> 23.846019 | J8: =SUMPRODUCT('Results_e,f'!$B8:$B10,Import!G8:G10)/$D8 -> 7.8456137 | K8: 7 | L8: 468001.2 | M8: -93.424368 | N8: -30.739835
A9: =Import!A9 -> 8 | B9: 155997.5 | K9: 8 | L9: 467999.24 | M9: -97.764264 | N9: -32.167783
A10: =Import!A10 -> 9 | B10: 155998.21 | K10: 9 | L10: 468000.98 | M10: -99.814183 | N10: -32.842064
A11: =Import!A11 -> 10 | B11: 155999.86 | C11: 4 | D11: =SUM(B11:B13) -> 468003.11 | E11: =SUMPRODUCT('Results_e,f'!$B11:$B13,Import!B11:B13)/$D11 -> -93.222038 | F11: =SUMPRODUCT('Results_e,f'!$B11:$B13,Import!C11:C13)/$D11 -> -30.673498 | G11: =SUMPRODUCT('Results_e,f'!$B11:$B13,Import!D11:D13)/$D11 -> 39.143469 | H11: =SUMPRODUCT('Results_e,f'!$B11:$B13,Import!E11:E13)/$D11 -> 154.55405 | I11: =SUMPRODUCT('Results_e,f'!$B11:$B13,Import!F11:F13)/$D11 -> 23.846321 | J11: =SUMPRODUCT('Results_e,f'!$B11:$B13,Import!G11:G13)/$D11 -> 7.8467996 | K11: 10 | L11: 467999.83 | M11: -74.593694 | N11: -24.543662
A12: =Import!A12 -> 11 | B12: 156001.7
A13: =Import!A13 -> 12 | B13: 156001.55 | K13: 1 | L13: {=_xlfn._xlws.FILTER(D38:D64,D38:D64<>"")} -> 166140.76 | O13: {=_xlfn._xlws.FILTER(E38:E64,E38:E64<>"")} -> -82.017769 | P13: {=_xlfn._xlws.FILTER(F38:F64,F38:F64<>"")} -> -26.983623
A14: =Import!A14 -> 13 | B14: 156000.88 | C14: 5 | D14: =SUM(B14:B16) -> 468000.7 | E14: =SUMPRODUCT('Results_e,f'!$B14:$B16,Import!B14:B16)/$D14 -> -92.821111 | F14: =SUMPRODUCT('Results_e,f'!$B14:$B16,Import!C14:C16)/$D14 -> -30.54099 | G14: =SUMPRODUCT('Results_e,f'!$B14:$B16,Import!D14:D16)/$D14 -> 39.142242 | H14: =SUMPRODUCT('Results_e,f'!$B14:$B16,Import!E14:E16)/$D14 -> 154.54799 | I14: =SUMPRODUCT('Results_e,f'!$B14:$B16,Import!F14:F16)/$D14 -> 23.846146 | J14: =SUMPRODUCT('Results_e,f'!$B14:$B16,Import!G14:G16)/$D14 -> 7.8461399 | K14: 2 | L14: 166139.82 | O14: -86.243291 | P14: -28.377603
A15: =Import!A15 -> 14 | B15: 156000.16 | K15: 3 | L15: 145727.84 | O15: -73.253269 | P15: -24.102645
A16: =Import!A16 -> 15 | B16: 155999.66 | K16: 4 | L16: 166139.91 | O16: -84.119613 | P16: -27.678643
A17: =Import!A17 -> 16 | B17: 155999.66 | C17: 6 | D17: =SUM(B17:B19) -> 467998.75 | E17: =SUMPRODUCT('Results_e,f'!$B17:$B19,Import!B17:B19)/$D17 -> -92.705719 | F17: =SUMPRODUCT('Results_e,f'!$B17:$B19,Import!C17:C19)/$D17 -> -30.503162 | G17: =SUMPRODUCT('Results_e,f'!$B17:$B19,Import!D17:D19)/$D17 -> 39.142009 | H17: =SUMPRODUCT('Results_e,f'!$B17:$B19,Import!E17:E19)/$D17 -> 154.54711 | I17: =SUMPRODUCT('Results_e,f'!$B17:$B19,Import!F17:F19)/$D17 -> 23.846133 | J17: =SUMPRODUCT('Results_e,f'!$B17:$B19,Import!G17:G19)/$D17 -> 7.8460789 | K17: 5 | L17: 145728 | O17: -73.374715 | P17: -24.143321
A18: =Import!A18 -> 17 | B18: 155999.66 | K18: 6 | L18: 166140 | O18: -83.879906 | P18: -27.599416
A19: =Import!A19 -> 18 | B19: 155999.42 | K19: 7 | L19: 145728.01 | O19: -72.454445 | P19: -23.839514
A20: =Import!A20 -> 19 | B20: 156000.16 | C20: 7 | D20: =SUM(B20:B22) -> 468001.2 | E20: =SUMPRODUCT('Results_e,f'!$B20:$B22,Import!B20:B22)/$D20 -> -93.424368 | F20: =SUMPRODUCT('Results_e,f'!$B20:$B22,Import!C20:C22)/$D20 -> -30.739835 | G20: =SUMPRODUCT('Results_e,f'!$B20:$B22,Import!D20:D22)/$D20 -> 39.144665 | H20: =SUMPRODUCT('Results_e,f'!$B20:$B22,Import!E20:E22)/$D20 -> 154.55817 | I20: =SUMPRODUCT('Results_e,f'!$B20:$B22,Import!F20:F22)/$D20 -> 23.846126 | J20: =SUMPRODUCT('Results_e,f'!$B20:$B22,Import!G20:G22)/$D20 -> 7.8460433 | K20: 8 | L20: 145728.09 | O20: -73.378352 | P20: -24.143365
A21: =Import!A21 -> 20 | B21: 156000.88 | K21: 9 | L21: 145728 | O21: -67.390114 | P21: -22.17334
A22: =Import!A22 -> 21 | B22: 156000.16
A23: =Import!A23 -> 22 | B23: 155999.92 | C23: 8 | D23: =SUM(B23:B25) -> 467999.24 | E23: =SUMPRODUCT('Results_e,f'!$B23:$B25,Import!B23:B25)/$D23 -> -97.764264 | F23: =SUMPRODUCT('Results_e,f'!$B23:$B25,Import!C23:C25)/$D23 -> -32.167783 | G23: =SUMPRODUCT('Results_e,f'!$B23:$B25,Import!D23:D25)/$D23 -> 39.265561 | H23: =SUMPRODUCT('Results_e,f'!$B23:$B25,Import!E23:E25)/$D23 -> 155.03568 | I23: =SUMPRODUCT('Results_e,f'!$B23:$B25,Import!F23:F25)/$D23 -> 23.846123 | J23: =SUMPRODUCT('Results_e,f'!$B23:$B25,Import!G23:G25)/$D23 -> 7.8460746
A24: =Import!A24 -> 23 | B24: 155999.66
A25: =Import!A25 -> 24 | B25: 155999.66
A26: =Import!A26 -> 25 | B26: 155999.93 | C26: 9 | D26: =SUM(B26:B28) -> 468000.98 | E26: =SUMPRODUCT('Results_e,f'!$B26:$B28,Import!B26:B28)/$D26 -> -99.814183 | F26: =SUMPRODUCT('Results_e,f'!$B26:$B28,Import!C26:C28)/$D26 -> -32.842064 | G26: =SUMPRODUCT('Results_e,f'!$B26:$B28,Import!D26:D28)/$D26 -> 39.28421 | H26: =SUMPRODUCT('Results_e,f'!$B26:$B28,Import!E26:E28)/$D26 -> 155.10924 | I26: =SUMPRODUCT('Results_e,f'!$B26:$B28,Import!F26:F28)/$D26 -> 23.846115 | J26: =SUMPRODUCT('Results_e,f'!$B26:$B28,Import!G26:G28)/$D26 -> 7.8460259
A27: =Import!A27 -> 26 | B27: 156000.17
A28: =Import!A28 -> 27 | B28: 156000.88
A29: =Import!A29 -> 28 | B29: 156000.02 | C29: 10 | D29: =SUM(B29:B31) -> 467999.83 | E29: =SUMPRODUCT('Results_e,f'!$B29:$B31,Import!B29:B31)/$D29 -> -74.593694 | F29: =SUMPRODUCT('Results_e,f'!$B29:$B31,Import!C29:C31)/$D29 -> -24.543662 | G29: =SUMPRODUCT('Results_e,f'!$B29:$B31,Import!D29:D31)/$D29 -> 39.523201 | H29: =SUMPRODUCT('Results_e,f'!$B29:$B31,Import!E29:E31)/$D29 -> 156.05294 | I29: =SUMPRODUCT('Results_e,f'!$B29:$B31,Import!F29:F31)/$D29 -> 23.846152 | J29: =SUMPRODUCT('Results_e,f'!$B29:$B31,Import!G29:G31)/$D29 -> 7.8461968
A30: =Import!A30 -> 29 | B30: 155999.8
A31: =Import!A31 -> 30 | B31: 156000.01
A32: =Import!A32 -> 31 | B32: 56800.178 | D32: =SUM(B32:B34) -> 170400.01
A33: =Import!A33 -> 32 | B33: 56799.915
A34: =Import!A34 -> 33 | B34: 56799.919
A35: =Import!A35 -> 34 | B35: 56800.76 | D35: =SUM(B35:B37) -> 170399.81
A36: =Import!A36 -> 35 | B36: 56799.526
A37: =Import!A37 -> 36 | B37: 56799.524 | E37: load case 1 | F37: load case 2
A38: =Import!A38 -> 37 | B38: 55380.485 | C38: 1 | D38: =SUM(B38:B40) -> 166140.76 | E38: =SUMPRODUCT('Results_e,f'!$B38:$B40,Import!H38:H40)/$D38 -> -82.017769 | F38: =SUMPRODUCT('Results_e,f'!$B38:$B40,Import!I38:I40)/$D38 -> -26.983623
A39: =Import!A39 -> 38 | B39: 55379.794
A40: =Import!A40 -> 39 | B40: 55380.486
...

Sheet Results_e_continued
A1: Panel ID | B1: XX, Case 1, Average | C1: XX, Case 2, Average | D1: XY, Case 1, Average | E1: XY, Case 2, Average | F1: YY, Case 1, Average | G1: YY, Case 2, Average | I1: Main Compression, Case 1, sigma_x,c | J1: Secondary Compression, Case 1, sigma_y,c | K1: Main Compression, Case 2, sigma_x,c | L1: Secondary Compression, Case 2, sigma_y,c | N1: Sigma, Case1 | O1: Sigma, Case2 | Q1: k_biax_i, case 1 | W1: k_biax_min, case1 | Y1: k_biax_i, case 2 | AE1: k_biax_min, case2 | AG1: sigma_cr,biax, case1 | AH1: sigma_cr,biax, case2 | AJ1: RF,biax,case1 | AK1: RF,biax,case2 | AM1: RF,shear,case1 | AN1: RF,shear,case2 | AP1: RF_panel,case1 | AQ1: RF_panel,case2
A2: ='Results_e,f'!C2 -> 1 | B2: ='Results_e,f'!E2 -> -55.413273 | C2: ='Results_e,f'!F2 -> -23.279955 | D2: ='Results_e,f'!G2 -> 39.399465 | E2: ='Results_e,f'!H2 -> 155.56517 | F2: ='Results_e,f'!I2 -> 23.846148 | G2: ='Results_e,f'!J2 -> 7.8462151 | I2: =MAX(-MIN(B2,0),-MIN(F2,0)) -> 55.413273 | J2: =IF(-MIN(B2,0)>=-MIN(F2,0),F2,B2) -> 23.846148 | K2: =MAX(-MIN(C2,0),-MIN(G2,0)) -> 23.279955 | L2: =IF(-MIN(C2,0)>=-MIN(G2,0),G2,C2) -> 7.8462151 | N2: =IF(J2>0,-J2/I2,ABS(J2)/I2) -> -0.43033278 | O2: =IF(L2>0,-L2/K2,ABS(L2)/K2) -> -0.33703738 | Q2: =((F$35^2+$B$40^2)^2)/($B$40^2*(F$35^2+$N2*$B$40^2)) -> -3.8674314 | R2: =((G$35^2+$B$40^2)^2)/($B$40^2*(G$35^2+$N2*$B$40^2)) -> 147.85069 | S2: =((H$35^2+$B$40^2)^2)/($B$40^2*(H$35^2+$N2*$B$40^2)) -> 7.0216432 | T2: =((I$35^2+$B$40^2)^2)/($B$40^2*(I$35^2+$N2*$B$40^2)) -> 5.7264299 | U2: =((J$35^2+$B$40^2)^2)/($B$40^2*(J$35^2+$N2*$B$40^2)) -> 6.0796334 | V2: =((K$35^2+$B$40^2)^2)/($B$40^2*(K$35^2+$N2*$B$40^2)) -> 7.0034539 | W2: =_xlfn.MINIFS(Q2:V2,Q2:V2,">0") -> 5.7264299 | Y2: =((F$35^2+$B$40^2)^2)/($B$40^2*(F$35^2+$O2*$B$40^2)) -> -5.4644725 | Z2: =((G$35^2+$B$40^2)^2)/($B$40^2*(G$35^2+$O2*$B$40^2)) -> 19.42535 | AA2: =((H$35^2+$B$40^2)^2)/($B$40^2*(H$35^2+$O2*$B$40^2)) -> 6.0335227 | AB2: =((I$35^2+$B$40^2)^2)/($B$40^2*(I$35^2+$O2*$B$40^2)) -> 5.355614 | AC2: =((J$35^2+$B$40^2)^2)/($B$40^2*(J$35^2+$O2*$B$40^2)) -> 5.8472441 | AD2: =((K$35^2+$B$40^2)^2)/($B$40^2*(K$35^2+$O2*$B$40^2)) -> 6.8250765 | AE2: =_xlfn.MINIFS(Y2:AD2,Y2:AD2,">0") -> 5.355614 | AG2: =W2*$B$41 -> 132.92773 | AH2: =AE2*$B$41 -> 124.31997 | AJ2: =1.5*I2 / AG2 -> 0.6253015 | AK2: =1.5*K2 / AH2 -> 0.28088755 | AM2: =ABS((D2*1.5) / $B$43) -> 0.44013741 | AN2: =ABS((E2*1.5) / $B$43) -> 1.7378422 | AP2: =1/((AJ2)+(AM2)^2) -> 1.2209678 | AQ2: =1/((AK2)+(AN2)^2) -> 0.30294006
A5: ='Results_e,f'!C5 -> 2 | B5: ='Results_e,f'!E5 -> -91.457956 | C5: ='Results_e,f'!F5 -> -30.092478 | D5: ='Results_e,f'!G5 -> 39.032757 | E5: ='Results_e,f'!H5 -> 154.11746 | F5: ='Results_e,f'!I5 -> 23.846153 | G5: ='Results_e,f'!J5 -> 7.8462545 | I5: =MAX(-MIN(B5,0),-MIN(F5,0)) -> 91.457956 | J5: =IF(-MIN(B5,0)>=-MIN(F5,0),F5,B5) -> 23.846153 | K5: =MAX(-MIN(C5,0),-MIN(G5,0)) -> 30.092478 | L5: =IF(-MIN(C5,0)>=-MIN(G5,0),G5,C5) -> 7.8462545 | N5: =IF(J5>0,-J5/I5,ABS(J5)/I5) -> -0.2607335 | O5: =IF(L5>0,-L5/K5,ABS(L5)/K5) -> -0.26073806 | Q5: =((F$35^2+$B$40^2)^2)/($B$40^2*(F$35^2+$N5*$B$40^2)) -> -8.2512246 | R5: =((G$35^2+$B$40^2)^2)/($B$40^2*(G$35^2+$N5*$B$40^2)) -> 11.357079 | S5: =((H$35^2+$B$40^2)^2)/($B$40^2*(H$35^2+$N5*$B$40^2)) -> 5.4107686 | T5: =((I$35^2+$B$40^2)^2)/($B$40^2*(I$35^2+$N5*$B$40^2)) -> 5.0862387 | U5: =((J$35^2+$B$40^2)^2)/($B$40^2*(J$35^2+$N5*$B$40^2)) -> 5.6699856 | V5: =((K$35^2+$B$40^2)^2)/($B$40^2*(K$35^2+$N5*$B$40^2)) -> 6.6858032 | W5: =_xlfn.MINIFS(Q5:V5,Q5:V5,">0") -> 5.0862387 | Y5: =((F$35^2+$B$40^2)^2)/($B$40^2*(F$35^2+$O5*$B$40^2)) -> -8.2509726 | Z5: =((G$35^2+$B$40^2)^2)/($B$40^2*(G$35^2+$O5*$B$40^2)) -> 11.357361 | AA5: =((H$35^2+$B$40^2)^2)/($B$40^2*(H$35^2+$O5*$B$40^2)) -> 5.4108021 | AB5: =((I$35^2+$B$40^2)^2)/($B$40^2*(I$35^2+$O5*$B$40^2)) -> 5.086254 | AC5: =((J$35^2+$B$40^2)^2)/($B$40^2*(J$35^2+$O5*$B$40^2)) -> 5.6699959 | AD5: =((K$35^2+$B$40^2)^2)/($B$40^2*(K$35^2+$O5*$B$40^2)) -> 6.6858114 | AE5: =_xlfn.MINIFS(Y5:AD5,Y5:AD5,">0") -> 5.086254 | AG5: =W5*$B$41 -> 118.06696 | AH5: =AE5*$B$41 -> 118.06732 | AJ5: =1.5*I5 / AG5 -> 1.1619418 | AK5: =1.5*K5 / AH5 -> 0.3823134 | AM5: =ABS((D5*1.5) / $B$43) -> 0.43604086 | AN5: =ABS((E5*1.5) / $B$43) -> 1.7216696 | AP5: =1/((AJ5)+(AM5)^2) -> 0.73960481 | AQ5: =1/((AK5)+(AN5)^2) -> 0.29882328
A8: ='Results_e,f'!C8 -> 3 | B8: ='Results_e,f'!E8 -> -93.46236 | C8: ='Results_e,f'!F8 -> -30.752011 | D8: ='Results_e,f'!G8 -> 39.135793 | E8: ='Results_e,f'!H8 -> 154.52201 | F8: ='Results_e,f'!I8 -> 23.846019 | G8: ='Results_e,f'!J8 -> 7.8456137 | I8: =MAX(-MIN(B8,0),-MIN(F8,0)) -> 93.46236 | J8: =IF(-MIN(B8,0)>=-MIN(F8,0),F8,B8) -> 23.846019 | K8: =MAX(-MIN(C8,0),-MIN(G8,0)) -> 30.752011 | L8: =IF(-MIN(C8,0)>=-MIN(G8,0),G8,C8) -> 7.8456137 | N8: =IF(J8>0,-J8/I8,ABS(J8)/I8) -> -0.25514035 | O8: =IF(L8>0,-L8/K8,ABS(L8)/K8) -> -0.25512522 | Q8: =((F$35^2+$B$40^2)^2)/($B$40^2*(F$35^2+$N8*$B$40^2)) -> -8.571648 | R8: =((G$35^2+$B$40^2)^2)/($B$40^2*(G$35^2+$N8*$B$40^2)) -> 11.021524 | S8: =((H$35^2+$B$40^2)^2)/($B$40^2*(H$35^2+$N8*$B$40^2)) -> 5.3701392 | T8: =((I$35^2+$B$40^2)^2)/($B$40^2*(I$35^2+$N8*$B$40^2)) -> 5.0675553 | U8: =((J$35^2+$B$40^2)^2)/($B$40^2*(J$35^2+$N8*$B$40^2)) -> 5.6574142 | V8: =((K$35^2+$B$40^2)^2)/($B$40^2*(K$35^2+$N8*$B$40^2)) -> 6.6758176 | W8: =_xlfn.MINIFS(Q8:V8,Q8:V8,">0") -> 5.0675553 | Y8: =((F$35^2+$B$40^2)^2)/($B$40^2*(F$35^2+$O8*$B$40^2)) -> -8.5725482 | Z8: =((G$35^2+$B$40^2)^2)/($B$40^2*(G$35^2+$O8*$B$40^2)) -> 11.020644 | AA8: =((H$35^2+$B$40^2)^2)/($B$40^2*(H$35^2+$O8*$B$40^2)) -> 5.3700301 | AB8: =((I$35^2+$B$40^2)^2)/($B$40^2*(I$35^2+$O8*$B$40^2)) -> 5.067505 | AC8: =((J$35^2+$B$40^2)^2)/($B$40^2*(J$35^2+$O8*$B$40^2)) -> 5.6573803 | AD8: =((K$35^2+$B$40^2)^2)/($B$40^2*(K$35^2+$O8*$B$40^2)) -> 6.6757906 | AE8: =_xlfn.MINIFS(Y8:AD8,Y8:AD8,">0") -> 5.067505 | AG8: =W8*$B$41 -> 117.63326 | AH8: =AE8*$B$41 -> 117.63209 | AJ8: =1.5*I8 / AG8 -> 1.1917849 | AK8: =1.5*K8 / AH8 -> 0.39213803 | AM8: =ABS((D8*1.5) / $B$43) -> 0.4371919 | AN8: =ABS((E8*1.5) / $B$43) -> 1.7261889 | AP8: =1/((AJ8)+(AM8)^2) -> 0.72310678 | AQ8: =1/((AK8)+(AN8)^2) -> 0.29657168
A11: ='Results_e,f'!C11 -> 4 | B11: ='Results_e,f'!E11 -> -93.222038 | C11: ='Results_e,f'!F11 -> -30.673498 | D11: ='Results_e,f'!G11 -> 39.143469 | E11: ='Results_e,f'!H11 -> 154.55405 | F11: ='Results_e,f'!I11 -> 23.846321 | G11: ='Results_e,f'!J11 -> 7.8467996 | I11: =MAX(-MIN(B11,0),-MIN(F11,0)) -> 93.222038 | J11: =IF(-MIN(B11,0)>=-MIN(F11,0),F11,B11) -> 23.846321 | K11: =MAX(-MIN(C11,0),-MIN(G11,0)) -> 30.673498 | L11: =IF(-MIN(C11,0)>=-MIN(G11,0),G11,C11) -> 7.8467996 | N11: =IF(J11>0,-J11/I11,ABS(J11)/I11) -> -0.25580132 | O11: =IF(L11>0,-L11/K11,ABS(L11)/K11) -> -0.25581691 | Q11: =((F$35^2+$B$40^2)^2)/($B$40^2*(F$35^2+$N11*$B$40^2)) -> -8.5324908 | R11: =((G$35^2+$B$40^2)^2)/($B$40^2*(G$35^2+$N11*$B$40^2)) -> 11.060142 | S11: =((H$35^2+$B$40^2)^2)/($B$40^2*(H$35^2+$N11*$B$40^2)) -> 5.3749088 | T11: =((I$35^2+$B$40^2)^2)/($B$40^2*(I$35^2+$N11*$B$40^2)) -> 5.0697561 | U11: =((J$35^2+$B$40^2)^2)/($B$40^2*(J$35^2+$N11*$B$40^2)) -> 5.658897 | V11: =((K$35^2+$B$40^2)^2)/($B$40^2*(K$35^2+$N11*$B$40^2)) -> 6.6769961 | W11: =_xlfn.MINIFS(Q11:V11,Q11:V11,">0") -> 5.0697561 | Y11: =((F$35^2+$B$40^2)^2)/($B$40^2*(F$35^2+$O11*$B$40^2)) -> -8.5315716 | Z11: =((G$35^2+$B$40^2)^2)/($B$40^2*(G$35^2+$O11*$B$40^2)) -> 11.061056 | AA11: =((H$35^2+$B$40^2)^2)/($B$40^2*(H$35^2+$O11*$B$40^2)) -> 5.3750214 | AB11: =((I$35^2+$B$40^2)^2)/($B$40^2*(I$35^2+$O11*$B$40^2)) -> 5.069808 | AC11: =((J$35^2+$B$40^2)^2)/($B$40^2*(J$35^2+$O11*$B$40^2)) -> 5.658932 | AD11: =((K$35^2+$B$40^2)^2)/($B$40^2*(K$35^2+$O11*$B$40^2)) -> 6.6770239 | AE11: =_xlfn.MINIFS(Y11:AD11,Y11:AD11,">0") -> 5.069808 | AG11: =W11*$B$41 -> 117.68435 | AH11: =AE11*$B$41 -> 117.68555 | AJ11: =1.5*I11 / AG11 -> 1.1882044 | AK11: =1.5*K11 / AH11 -> 0.39095918 | AM11: =ABS((D11*1.5) / $B$43) -> 0.43727764 | AN11: =ABS((E11*1.5) / $B$43) -> 1.7265468 | AP11: =1/((AJ11)+(AM11)^2) -> 0.72494441 | AQ11: =1/((AK11)+(AN11)^2) -> 0.29656667
A14: ='Results_e,f'!C14 -> 5 | B14: ='Results_e,f'!E14 -> -92.821111 | C14: ='Results_e,f'!F14 -> -30.54099 | D14: ='Results_e,f'!G14 -> 39.142242 | E14: ='Results_e,f'!H14 -> 154.54799 | F14: ='Results_e,f'!I14 -> 23.846146 | G14: ='Results_e,f'!J14 -> 7.8461399 | I14: =MAX(-MIN(B14,0),-MIN(F14,0)) -> 92.821111 | J14: =IF(-MIN(B14,0)>=-MIN(F14,0),F14,B14) -> 23.846146 | K14: =MAX(-MIN(C14,0),-MIN(G14,0)) -> 30.54099 | L14: =IF(-MIN(C14,0)>=-MIN(G14,0),G14,C14) -> 7.8461399 | N14: =IF(J14>0,-J14/I14,ABS(J14)/I14) -> -0.25690434 | O14: =IF(L14>0,-L14/K14,ABS(L14)/K14) -> -0.25690523 | Q14: =((F$35^2+$B$40^2)^2)/($B$40^2*(F$35^2+$N14*$B$40^2)) -> -8.4679372 | R14: =((G$35^2+$B$40^2)^2)/($B$40^2*(G$35^2+$N14*$B$40^2)) -> 11.125192 | S14: =((H$35^2+$B$40^2)^2)/($B$40^2*(H$35^2+$N14*$B$40^2)) -> 5.382887 | T14: =((I$35^2+$B$40^2)^2)/($B$40^2*(I$35^2+$N14*$B$40^2)) -> 5.0734329 | U14: =((J$35^2+$B$40^2)^2)/($B$40^2*(J$35^2+$N14*$B$40^2)) -> 5.661373 | V14: =((K$35^2+$B$40^2)^2)/($B$40^2*(K$35^2+$N14*$B$40^2)) -> 6.6789637 | W14: =_xlfn.MINIFS(Q14:V14,Q14:V14,">0") -> 5.0734329 | Y14: =((F$35^2+$B$40^2)^2)/($B$40^2*(F$35^2+$O14*$B$40^2)) -> -8.4678856 | Z14: =((G$35^2+$B$40^2)^2)/($B$40^2*(G$35^2+$O14*$B$40^2)) -> 11.125245 | AA14: =((H$35^2+$B$40^2)^2)/($B$40^2*(H$35^2+$O14*$B$40^2)) -> 5.3828935 | AB14: =((I$35^2+$B$40^2)^2)/($B$40^2*(I$35^2+$O14*$B$40^2)) -> 5.0734359 | AC14: =((J$35^2+$B$40^2)^2)/($B$40^2*(J$35^2+$O14*$B$40^2)) -> 5.661375 | AD14: =((K$35^2+$B$40^2)^2)/($B$40^2*(K$35^2+$O14*$B$40^2)) -> 6.6789653 | AE14: =_xlfn.MINIFS(Y14:AD14,Y14:AD14,">0") -> 5.0734359 | AG14: =W14*$B$41 -> 117.7697 | AH14: =AE14*$B$41 -> 117.76977 | AJ14: =1.5*I14 / AG14 -> 1.1822367 | AK14: =1.5*K14 / AH14 -> 0.38899189 | AM14: =ABS((D14*1.5) / $B$43) -> 0.43726394 | AN14: =ABS((E14*1.5) / $B$43) -> 1.7264791 | AP14: =1/((AJ14)+(AM14)^2) -> 0.72810064 | AQ14: =1/((AK14)+(AN14)^2) -> 0.29676038
A17: ='Results_e,f'!C17 -> 6 | B17: ='Results_e,f'!E17 -> -92.705719 | C17: ='Results_e,f'!F17 -> -30.503162 | D17: ='Results_e,f'!G17 -> 39.142009 | E17: ='Results_e,f'!H17 -> 154.54711 | F17: ='Results_e,f'!I17 -> 23.846133 | G17: ='Results_e,f'!J17 -> 7.8460789 | I17: =MAX(-MIN(B17,0),-MIN(F17,0)) -> 92.705719 | J17: =IF(-MIN(B17,0)>=-MIN(F17,0),F17,B17) -> 23.846133 | K17: =MAX(-MIN(C17,0),-MIN(G17,0)) -> 30.503162 | L17: =IF(-MIN(C17,0)>=-MIN(G17,0),G17,C17) -> 7.8460789 | N17: =IF(J17>0,-J17/I17,ABS(J17)/I17) -> -0.25722397 | O17: =IF(L17>0,-L17/K17,ABS(L17)/K17) -> -0.25722182 | Q17: =((F$35^2+$B$40^2)^2)/($B$40^2*(F$35^2+$N17*$B$40^2)) -> -8.4494132 | R17: =((G$35^2+$B$40^2)^2)/($B$40^2*(G$35^2+$N17*$B$40^2)) -> 11.144186 | S17: =((H$35^2+$B$40^2)^2)/($B$40^2*(H$35^2+$N17*$B$40^2)) -> 5.3852034 | T17: =((I$35^2+$B$40^2)^2)/($B$40^2*(I$35^2+$N17*$B$40^2)) -> 5.0744994 | U17: =((J$35^2+$B$40^2)^2)/($B$40^2*(J$35^2+$N17*$B$40^2)) -> 5.662091 | V17: =((K$35^2+$B$40^2)^2)/($B$40^2*(K$35^2+$N17*$B$40^2)) -> 6.6795341 | W17: =_xlfn.MINIFS(Q17:V17,Q17:V17,">0") -> 5.0744994 | Y17: =((F$35^2+$B$40^2)^2)/($B$40^2*(F$35^2+$O17*$B$40^2)) -> -8.4495373 | Z17: =((G$35^2+$B$40^2)^2)/($B$40^2*(G$35^2+$O17*$B$40^2)) -> 11.144058 | AA17: =((H$35^2+$B$40^2)^2)/($B$40^2*(H$35^2+$O17*$B$40^2)) -> 5.3851878 | AB17: =((I$35^2+$B$40^2)^2)/($B$40^2*(I$35^2+$O17*$B$40^2)) -> 5.0744922 | AC17: =((J$35^2+$B$40^2)^2)/($B$40^2*(J$35^2+$O17*$B$40^2)) -> 5.6620861 | AD17: =((K$35^2+$B$40^2)^2)/($B$40^2*(K$35^2+$O17*$B$40^2)) -> 6.6795302 | AE17: =_xlfn.MINIFS(Y17:AD17,Y17:AD17,">0") -> 5.0744922 | AG17: =W17*$B$41 -> 117.79446 | AH17: =AE17*$B$41 -> 117.79429 | AJ17: =1.5*I17 / AG17 -> 1.1805189 | AK17: =1.5*K17 / AH17 -> 0.38842921 | AM17: =ABS((D17*1.5) / $B$43) -> 0.43726134 | AN17: =ABS((E17*1.5) / $B$43) -> 1.7264693 | AP17: =1/((AJ17)+(AM17)^2) -> 0.72901369 | AQ17: =1/((AK17)+(AN17)^2) -> 0.29681293
A20: ='Results_e,f'!C20 -> 7 | B20: ='Results_e,f'!E20 -> -93.424368 | C20: ='Results_e,f'!F20 -> -30.739835 | D20: ='Results_e,f'!G20 -> 39.144665 | E20: ='Results_e,f'!H20 -> 154.55817 | F20: ='Results_e,f'!I20 -> 23.846126 | G20: ='Results_e,f'!J20 -> 7.8460433 | I20: =MAX(-MIN(B20,0),-MIN(F20,0)) -> 93.424368 | J20: =IF(-MIN(B20,0)>=-MIN(F20,0),F20,B20) -> 23.846126 | K20: =MAX(-MIN(C20,0),-MIN(G20,0)) -> 30.739835 | L20: =IF(-MIN(C20,0)>=-MIN(G20,0),G20,C20) -> 7.8460433 | N20: =IF(J20>0,-J20/I20,ABS(J20)/I20) -> -0.25524525 | O20: =IF(L20>0,-L20/K20,ABS(L20)/K20) -> -0.25524025 | Q20: =((F$35^2+$B$40^2)^2)/($B$40^2*(F$35^2+$N20*$B$40^2)) -> -8.5654093 | R20: =((G$35^2+$B$40^2)^2)/($B$40^2*(G$35^2+$N20*$B$40^2)) -> 11.027636 | S20: =((H$35^2+$B$40^2)^2)/($B$40^2*(H$35^2+$N20*$B$40^2)) -> 5.3708956 | T20: =((I$35^2+$B$40^2)^2)/($B$40^2*(I$35^2+$N20*$B$40^2)) -> 5.0679045 | U20: =((J$35^2+$B$40^2)^2)/($B$40^2*(J$35^2+$N20*$B$40^2)) -> 5.6576495 | V20: =((K$35^2+$B$40^2)^2)/($B$40^2*(K$35^2+$N20*$B$40^2)) -> 6.6760046 | W20: =_xlfn.MINIFS(Q20:V20,Q20:V20,">0") -> 5.0679045 | Y20: =((F$35^2+$B$40^2)^2)/($B$40^2*(F$35^2+$O20*$B$40^2)) -> -8.5657062 | Z20: =((G$35^2+$B$40^2)^2)/($B$40^2*(G$35^2+$O20*$B$40^2)) -> 11.027344 | AA20: =((H$35^2+$B$40^2)^2)/($B$40^2*(H$35^2+$O20*$B$40^2)) -> 5.3708596 | AB20: =((I$35^2+$B$40^2)^2)/($B$40^2*(I$35^2+$O20*$B$40^2)) -> 5.0678878 | AC20: =((J$35^2+$B$40^2)^2)/($B$40^2*(J$35^2+$O20*$B$40^2)) -> 5.6576383 | AD20: =((K$35^2+$B$40^2)^2)/($B$40^2*(K$35^2+$O20*$B$40^2)) -> 6.6759957 | AE20: =_xlfn.MINIFS(Y20:AD20,Y20:AD20,">0") -> 5.0678878 | AG20: =W20*$B$41 -> 117.64137 | AH20: =AE20*$B$41 -> 117.64098 | AJ20: =1.5*I20 / AG20 -> 1.1912183 | AK20: =1.5*K20 / AH20 -> 0.39195314 | AM20: =ABS((D20*1.5) / $B$43) -> 0.43729101 | AN20: =ABS((E20*1.5) / $B$43) -> 1.7265928 | AP20: =1/((AJ20)+(AM20)^2) -> 0.72335778 | AQ20: =1/((AK20)+(AN20)^2) -> 0.29646532
A23: ='Results_e,f'!C23 -> 8 | B23: ='Results_e,f'!E23 -> -97.764264 | C23: ='Results_e,f'!F23 -> -32.167783 | D23: ='Results_e,f'!G23 -> 39.265561 | E23: ='Results_e,f'!H23 -> 155.03568 | F23: ='Results_e,f'!I23 -> 23.846123 | G23: ='Results_e,f'!J23 -> 7.8460746 | I23: =MAX(-MIN(B23,0),-MIN(F23,0)) -> 97.764264 | J23: =IF(-MIN(B23,0)>=-MIN(F23,0),F23,B23) -> 23.846123 | K23: =MAX(-MIN(C23,0),-MIN(G23,0)) -> 32.167783 | L23: =IF(-MIN(C23,0)>=-MIN(G23,0),G23,C23) -> 7.8460746 | N23: =IF(J23>0,-J23/I23,ABS(J23)/I23) -> -0.24391451 | O23: =IF(L23>0,-L23/K23,ABS(L23)/K23) -> -0.24391095 | Q23: =((F$35^2+$B$40^2)^2)/($B$40^2*(F$35^2+$N23*$B$40^2)) -> -9.2962068 | R23: =((G$35^2+$B$40^2)^2)/($B$40^2*(G$35^2+$N23*$B$40^2)) -> 10.40453 | S23: =((H$35^2+$B$40^2)^2)/($B$40^2*(H$35^2+$N23*$B$40^2)) -> 5.2904071 | T23: =((I$35^2+$B$40^2)^2)/($B$40^2*(I$35^2+$N23*$B$40^2)) -> 5.0304676 | U23: =((J$35^2+$B$40^2)^2)/($B$40^2*(J$35^2+$N23*$B$40^2)) -> 5.6323501 | V23: =((K$35^2+$B$40^2)^2)/($B$40^2*(K$35^2+$N23*$B$40^2)) -> 6.6558656 | W23: =_xlfn.MINIFS(Q23:V23,Q23:V23,">0") -> 5.0304676 | Y23: =((F$35^2+$B$40^2)^2)/($B$40^2*(F$35^2+$O23*$B$40^2)) -> -9.2964561 | Z23: =((G$35^2+$B$40^2)^2)/($B$40^2*(G$35^2+$O23*$B$40^2)) -> 10.404346 | AA23: =((H$35^2+$B$40^2)^2)/($B$40^2*(H$35^2+$O23*$B$40^2)) -> 5.2903822 | AB23: =((I$35^2+$B$40^2)^2)/($B$40^2*(I$35^2+$O23*$B$40^2)) -> 5.0304559 | AC23: =((J$35^2+$B$40^2)^2)/($B$40^2*(J$35^2+$O23*$B$40^2)) -> 5.6323422 | AD23: =((K$35^2+$B$40^2)^2)/($B$40^2*(K$35^2+$O23*$B$40^2)) -> 6.6558592 | AE23: =_xlfn.MINIFS(Y23:AD23,Y23:AD23,">0") -> 5.0304559 | AG23: =W23*$B$41 -> 116.77234 | AH23: =AE23*$B$41 -> 116.77207 | AJ23: =1.5*I23 / AG23 -> 1.2558316 | AK23: =1.5*K23 / AH23 -> 0.41321245 | AM23: =ABS((D23*1.5) / $B$43) -> 0.43864155 | AN23: =ABS((E23*1.5) / $B$43) -> 1.7319271 | AP23: =1/((AJ23)+(AM23)^2) -> 0.69049425 | AQ23: =1/((AK23)+(AN23)^2) -> 0.2930159
A26: ='Results_e,f'!C26 -> 9 | B26: ='Results_e,f'!E26 -> -99.814183 | C26: ='Results_e,f'!F26 -> -32.842064 | D26: ='Results_e,f'!G26 -> 39.28421 | E26: ='Results_e,f'!H26 -> 155.10924 | F26: ='Results_e,f'!I26 -> 23.846115 | G26: ='Results_e,f'!J26 -> 7.8460259 | I26: =MAX(-MIN(B26,0),-MIN(F26,0)) -> 99.814183 | J26: =IF(-MIN(B26,0)>=-MIN(F26,0),F26,B26) -> 23.846115 | K26: =MAX(-MIN(C26,0),-MIN(G26,0)) -> 32.842064 | L26: =IF(-MIN(C26,0)>=-MIN(G26,0),G26,C26) -> 7.8460259 | N26: =IF(J26>0,-J26/I26,ABS(J26)/I26) -> -0.23890508 | O26: =IF(L26>0,-L26/K26,ABS(L26)/K26) -> -0.23890173 | Q26: =((F$35^2+$B$40^2)^2)/($B$40^2*(F$35^2+$N26*$B$40^2)) -> -9.6606117 | R26: =((G$35^2+$B$40^2)^2)/($B$40^2*(G$35^2+$N26*$B$40^2)) -> 10.15095 | S26: =((H$35^2+$B$40^2)^2)/($B$40^2*(H$35^2+$N26*$B$40^2)) -> 5.2555862 | T26: =((I$35^2+$B$40^2)^2)/($B$40^2*(I$35^2+$N26*$B$40^2)) -> 5.0140921 | U26: =((J$35^2+$B$40^2)^2)/($B$40^2*(J$35^2+$N26*$B$40^2)) -> 5.6212369 | V26: =((K$35^2+$B$40^2)^2)/($B$40^2*(K$35^2+$N26*$B$40^2)) -> 6.6470005 | W26: =_xlfn.MINIFS(Q26:V26,Q26:V26,">0") -> 5.0140921 | Y26: =((F$35^2+$B$40^2)^2)/($B$40^2*(F$35^2+$O26*$B$40^2)) -> -9.660865 | Z26: =((G$35^2+$B$40^2)^2)/($B$40^2*(G$35^2+$O26*$B$40^2)) -> 10.150784 | AA26: =((H$35^2+$B$40^2)^2)/($B$40^2*(H$35^2+$O26*$B$40^2)) -> 5.2555631 | AB26: =((I$35^2+$B$40^2)^2)/($B$40^2*(I$35^2+$O26*$B$40^2)) -> 5.0140811 | AC26: =((J$35^2+$B$40^2)^2)/($B$40^2*(J$35^2+$O26*$B$40^2)) -> 5.6212295 | AD26: =((K$35^2+$B$40^2)^2)/($B$40^2*(K$35^2+$O26*$B$40^2)) -> 6.6469946 | AE26: =_xlfn.MINIFS(Y26:AD26,Y26:AD26,">0") -> 5.0140811 | AG26: =W26*$B$41 -> 116.39222 | AH26: =AE26*$B$41 -> 116.39197 | AJ26: =1.5*I26 / AG26 -> 1.2863512 | AK26: =1.5*K26 / AH26 -> 0.42325169 | AM26: =ABS((D26*1.5) / $B$43) -> 0.43884988 | AN26: =ABS((E26*1.5) / $B$43) -> 1.7327489 | AP26: =1/((AJ26)+(AM26)^2) -> 0.67615975 | AQ26: =1/((AK26)+(AN26)^2) -> 0.29191365
A29: ='Results_e,f'!C29 -> 10 | B29: ='Results_e,f'!E29 -> -74.593694 | C29: ='Results_e,f'!F29 -> -24.543662 | D29: ='Results_e,f'!G29 -> 39.523201 | E29: ='Results_e,f'!H29 -> 156.05294 | F29: ='Results_e,f'!I29 -> 23.846152 | G29: ='Results_e,f'!J29 -> 7.8461968 | I29: =MAX(-MIN(B29,0),-MIN(F29,0)) -> 74.593694 | J29: =IF(-MIN(B29,0)>=-MIN(F29,0),F29,B29) -> 23.846152 | K29: =MAX(-MIN(C29,0),-MIN(G29,0)) -> 24.543662 | L29: =IF(-MIN(C29,0)>=-MIN(G29,0),G29,C29) -> 7.8461968 | N29: =IF(J29>0,-J29/I29,ABS(J29)/I29) -> -0.31968053 | O29: =IF(L29>0,-L29/K29,ABS(L29)/K29) -> -0.31968322 | Q29: =((F$35^2+$B$40^2)^2)/($B$40^2*(F$35^2+$N29*$B$40^2)) -> -5.9192182 | R29: =((G$35^2+$B$40^2)^2)/($B$40^2*(G$35^2+$N29*$B$40^2)) -> 16.722943 | S29: =((H$35^2+$B$40^2)^2)/($B$40^2*(H$35^2+$N29*$B$40^2)) -> 5.8795907 | T29: =((I$35^2+$B$40^2)^2)/($B$40^2*(I$35^2+$N29*$B$40^2)) -> 5.291862 | U29: =((J$35^2+$B$40^2)^2)/($B$40^2*(J$35^2+$N29*$B$40^2)) -> 5.8059562 | V29: =((K$35^2+$B$40^2)^2)/($B$40^2*(K$35^2+$N29*$B$40^2)) -> 6.7928886 | W29: =_xlfn.MINIFS(Q29:V29,Q29:V29,">0") -> 5.291862 | Y29: =((F$35^2+$B$40^2)^2)/($B$40^2*(F$35^2+$O29*$B$40^2)) -> -5.9191419 | Z29: =((G$35^2+$B$40^2)^2)/($B$40^2*(G$35^2+$O29*$B$40^2)) -> 16.723303 | AA29: =((H$35^2+$B$40^2)^2)/($B$40^2*(H$35^2+$O29*$B$40^2)) -> 5.8796139 | AB29: =((I$35^2+$B$40^2)^2)/($B$40^2*(I$35^2+$O29*$B$40^2)) -> 5.2918717 | AC29: =((J$35^2+$B$40^2)^2)/($B$40^2*(J$35^2+$O29*$B$40^2)) -> 5.8059625 | AD29: =((K$35^2+$B$40^2)^2)/($B$40^2*(K$35^2+$O29*$B$40^2)) -> 6.7928935 | AE29: =_xlfn.MINIFS(Y29:AD29,Y29:AD29,">0") -> 5.2918717 | AG29: =W29*$B$41 -> 122.8401 | AH29: =AE29*$B$41 -> 122.84032 | AJ29: =1.5*I29 / AG29 -> 0.91086333 | AK29: =1.5*K29 / AH29 -> 0.29970202 | AM29: =ABS((D29*1.5) / $B$43) -> 0.44151969 | AN29: =ABS((E29*1.5) / $B$43) -> 1.7432911 | AP29: =1/((AJ29)+(AM29)^2) -> 0.90432023 | AQ29: =1/((AK29)+(AN29)^2) -> 0.29951187
A35: E_b | B35: 65643.64 | D35: find out k_biax | E35: m | F35: 1 | G35: 2 | H35: 3 | I35: 4 | J35: 5 | K35: 6
A36: muh | B36: 0.34
A37: a | B37: 600
A38: b | B38: 200
A39: t | B39: 3.9
A40: alpha | B40: =B37/B38 -> 3
A41: sigma_e | B41: =($B$35*PI()^2)/(12*(1-$B$36^2))*($B$39/$B$38)^2 -> 23.21302
A42: k_tau | B42: =5.34 + 4/B40^2 -> 5.7844444
A43: tau_cr | B43: =B41*B42 -> 134.27442

Sheet f_Crippling
A1: T-section | D1: Omega-Section | L1: Calculating Crossection properties | P1: T-section | S1: Omega-section | Y1: T-section | AA1: Omega-section
A2: Number | B2: 4 | D2: Number | E2: 5 | G2: Yield | H2: 491.79 | P2: w_eff | Q2: =Results_e_continued!B38 -> 200 | V2: L | W2: =Results_e_continued!B37 -> 600 | Y2: 1 | AA2: 3
A3: DIM1 | B3: 65 | D3: DIM1 | E3: 28 | G3: E-b-basis | H3: 65643.64 | P3: t_thickness_skin | Q3: 3.9 | V3: c | W3: 1 | Y3: 2 | AA3: 5
A4: DIM2 | B4: 42 | D4: DIM2 | E4: 2.4 | G4: E | H4: 72439.05 | Y4: 4 | AA4: 7
A5: DIM3 | B5: 3 | D5: DIM3 | E5: 20 | P5: z_EC_Zaehler | Q5: =(-(Q3/2) * Q2*Q3 + (B5/2)*B5*B3 + (B5+(B4-B5)/2) * B6 * (B4-B5)) -> 614.25 | S5: z_EC_Zaehler | T5: =(-Q3/2 * Q2*Q3 + 2*(E6*E4)*(E4/2) + 2*((E3/2)*E4*E3) + (((E3-E4)+E4/2)*(E5-2*E4)*E4)) -> 1424.664 | Y5: 6 | AA5: 8
A6: DIM4 | B6: 2.1 | D6: DIM4 | E6: 15 | P6: Total Area | Q6: =Q2*Q3 + B3*B5 + (B4-B5)*B6 -> 1056.9 | S6: Total Area | T6: =Q2*Q3 + E4*(2*E6+2*E3+(E5-2*E4)) -> 1022.88 | AA6: 9
P7: z_EC | Q7: =Q5/Q6 -> 0.58118081 | S7: z_EC | T7: =T5/T6 -> 1.3927968
A8: a_1_2 | B8: =B4 -> 42 | D8: a_1 | E8: =E3 -> 28
A9: t2 | B9: =B6 -> 2.1 | D9: a_2 | E9: =E5 -> 20 | P9: Iy,1 | Q9: =(Q2*(Q3^3)) / 12 + Q2*Q3*(Q7+Q3/2)^2 -> 5986.0135 | S9: Iy,0 | T9: =(Q2*Q3^3) / 12 + Q2*Q3*(Q3/2 + T7)^2 -> 9704.5966
A10: a_1_1 | B10: =B3/2 -> 32.5 | D10: a_flange | E10: =E6+E4 -> 17.4 | P10: Iy,2 | Q10: =(B3*(B5^3))/12 + B3*B5*(B5/2 - Q7)^2 -> 310.8746 | S10: Iy,1 | T10: =(E6*(E4^3)) / 12 + E6*E4*((E4/2-T7)^2) -> 18.618142
A11: t1 | B11: =B5 -> 3 | D11: t1 | E11: =E4 -> 2.4 | P11: Iy,3 | Q11: =(B6*((B4-B5)^3)/12) + B6*(B4-B5)*(((B4+B5)/2)-Q7)^2 -> 49728.422 | S11: Iy,2 | T11: =(E4*(E3^3))/ 12 + E3*E4*(E3/2 - T7)^2 -> 15071.274
D12: t2 | E12: =E4 -> 2.4 | S12: Iy,3 | T12: =((E5-2*E4)*(E4^3))/12 + (E5-2*E4)*E4*(E3-E4/2 - T7)^2 -> 23566.298
A13: b_1_1 | B13: =$B$10-($B$9/2) * (0.25 * ($B$9/$B$11)) -> 32.31625 | D13: r | E13: 0 | P13: Iy,ges | Q13: =SUM(Q9:Q11) -> 56025.31 | S13: Iy,ges | T13: =T9+2*T10+2*T11+T12 -> 63450.678
A14: b_1_2 | B14: =$B$8-($B$11/2) * (2- 0.5 * ($B$9/$B$11)) -> 39.525 | D14: b1_omega_twoconnected | E14: =E8-E12 -> 25.6
A15: K | B15: 0.41 | D15: b2_omega_twoconnected | E15: =E9-E11 -> 17.6 | P15: r | Q15: =SQRT(Q13/Q6) -> 7.2807343 | S15: r | T15: =SQRT(T13/T6) -> 7.8760015
A16: x_1 | B16: =(B13/B11)*SQRT(H2/(B15*H3)) -> 1.4561338 | D16: b1_omega_flange | E16: =E10 - E11/2 -> 16.2 | P16: lamda | Q16: =W3*W2 / Q15 -> 82.40927 | S16: lamda | T16: =W3*W2 / T15 -> 76.180788
A17: x_2 | B17: =(B14/B9)*SQRT(H2/(B15*H3)) -> 2.5442171
D18: K_flange | E18: 0.41 | P18: sigma_cutoff | Q18: =f_Crippling!B24 -> 394.86591 | S18: sigma_cutoff | T18: =f_Crippling!E30 -> 491.79
A19: a_1 | B19: =IF(B16<0.4,NA(),IF(B16<=1.095,1.4-0.628*B16,IF(B16<=1.633,0.78/B16,0.69/(B16^0.75)))) -> 0.53566505 | D19: K_two_connected | E19: 3.6 | P19: lamda_crit | Q19: =SQRT((2*(PI()^2)*f_Crippling!$H$3)/(f_Crippling!Q18)) -> 57.284401 | S19: lamda_crit | T19: =SQRT((2*(PI()^2)*f_Crippling!$H$3)/(f_Crippling!T18)) -> 51.33001
A20: a_2 | B20: =IF(B17<0.4,NA(),IF(B17<=1.095,1.4-0.628*B17,IF(B17<=1.633,0.78/B17,0.69/(B17^0.75)))) -> 0.34251805 | D20: x1 | E20: =(E14/E11)*SQRT($H$2/(E19*$H$3)) -> 0.48659875
A21: sigma_crip,1 | B21: =B19*H2 -> 263.43471 | D21: x2 | E21: =(E15/E12)*SQRT($H$2/(E19*$H$3)) -> 0.33453664 | F21: <- as a2 is smaller than 0.4 sigma_crip = sigma_yield
A22: sigma_crip,2 | B22: =B20*H2 -> 168.44695 | D22: x3 | E22: =(E16/E12)*SQRT($H$2/(E18*$H$3)) -> 0.9124422 | P22: Euler-Johnson or Euler
A23: sigma_avg | B23: =(B22*B14*B9 + 2*H2*B13*B11) / (2*B13*B11 + B14*B9) -> 394.86591 | D23: a1 | E23: =IF(E20<0.4,NA(),IF(E20<=1.095,1.4-0.628*E20,IF(E20<=1.633,0.78/E20,0.69/(E20^0.75)))) -> 1.094416 | P23: sigma_crit | Q23: =IF(Q16<Q19,Q18-1/$H$3*((Q18/(2*PI()))^2)*Q16^2,PI()^2*$H$3/Q16^2) -> 95.398219 | S23: sigma_crit | T23: =IF(T16<T19,T18-1/$H$3*((T18/(2*PI()))^2)*T16^2,PI()^2*$H$3/T16^2) -> 111.63528
A24: sigma_cutoff | B24: =MIN(H2,B23) -> 394.86591 | D24: a2 | E24: =IF(E21<0.4,NA(),IF(E21<=1.095,1.4-0.628*E21,IF(E21<=1.633,0.78/E21,0.69/(E21^0.75)))) -> #N/A
D25: a3 | E25: =IF(E22<0.4,NA(),IF(E22<=1.095,1.4-0.628*E22,IF(E22<=1.633,0.78/E22,0.69/(E22^0.75)))) -> 0.8269863
D26: sigma_crip,1 | E26: =E23*H2 -> 538.22284
D27: sigma_crip,2 | E27: =H2 -> 491.79 | V27: wha t is important crtical sigma or crip wat to enter, crit is for RF right but crip is used to determine crit right?
D29: sigma_avg | E29: =(2*E26*E14*E11 +E27*E15*E12 + 2*H2*E16*E4) / (2*E14*E11 + E15*E12 + 2*E16*E4) -> 515.28171
D30: sigma_cutoff | E30: =MIN((E26*E14*E11+E27*E15*E12)/(E14*E11+E15*E12),$H$2) -> 491.79

Sheet f_RF
B1: case 1 | F1: case 2
B2: Stringer ID | C2: Axial Stress | D2: sigma_crit | E2: RF | G2: Axial Stress | H2: sigma_crit | I2: RF
B3: 1 | C3: =C16 -> -75.684082 | D3: =E28 -> 95.398219 | E3: =D3/ABS(1.5*C3) -> 0.84031953 | G3: =D16 -> -26.764135 | H3: =E28 -> 95.398219 | I3: =H3/ABS(1.5*G3) -> 2.3762701
B4: 2 | C4: =C17 -> -90.831377 | D4: =E29 -> 95.398219 | E4: =D4/ABS(1.5*C4) -> 0.7001855 | G4: =D17 -> -29.886561 | H4: =E29 -> 95.398219 | I4: =H4/ABS(1.5*G4) -> 2.1280071
B5: 3 | C5: =C18 -> -88.572137 | D5: =E30 -> 111.63528 | E5: =D5/ABS(1.5*C5) -> 0.84025886 | G5: =D18 -> -29.143202 | H5: =E30 -> 111.63528 | I5: =H5/ABS(1.5*G5) -> 2.5537181
B6: 4 | C6: =C19 -> -90.689335 | D6: =E31 -> 95.398219 | E6: =D6/ABS(1.5*C6) -> 0.70128216 | G6: =D19 -> -29.839975 | H6: =E31 -> 95.398219 | I6: =H6/ABS(1.5*G6) -> 2.1313293
B7: 5 | C7: =C20 -> -88.15962 | D7: =E32 -> 111.63528 | E7: =D7/ABS(1.5*C7) -> 0.8441906 | G7: =D20 -> -29.007457 | H7: =E32 -> 111.63528 | I7: =H7/ABS(1.5*G7) -> 2.5656686
B8: 6 | C8: =C21 -> -90.658606 | D8: =E33 -> 95.398219 | E8: =D8/ABS(1.5*C8) -> 0.70151986 | G8: =D21 -> -29.829735 | H8: =E33 -> 95.398219 | I8: =H8/ABS(1.5*G8) -> 2.1320609
B9: 7 | C9: =C22 -> -90.099817 | D9: =E34 -> 111.63528 | E9: =D9/ABS(1.5*C9) -> 0.82601192 | G9: =D22 -> -29.645815 | H9: =E34 -> 111.63528 | I9: =H9/ABS(1.5*G9) -> 2.5104225
B10: 8 | C10: =C23 -> -92.755483 | D10: =E35 -> 111.63528 | E10: =D10/ABS(1.5*C10) -> 0.80236251 | G10: =D23 -> -30.519495 | H10: =E35 -> 111.63528 | I10: =H10/ABS(1.5*G10) -> 2.4385568
B11: 9 | C11: =C24 -> -82.499216 | D11: =E36 -> 111.63528 | E11: =D11/ABS(1.5*C11) -> 0.90211188 | G11: =D24 -> -27.144825 | H11: =E36 -> 111.63528 | I11: =H11/ABS(1.5*G11) -> 2.7417204
B14: Berechnung volumen gemittelter Wert zusammen mit Skin
B15: Stringer ID | C15: case 1 | D15: case 2
B16: 1 | C16: =('Results_e,f'!M2*'Results_e,f'!$L2/2+'Results_e,f'!M3*'Results_e,f'!$L3/2+'Results_e,f'!O13*'Results_e,f'!$L13)/(('Results_e,f'!$L2/2)+('Results_e,f'!$L3/2)+'Results_e,f'!$L13) -> -75.684082 | D16: =('Results_e,f'!N2*'Results_e,f'!$L2/2+'Results_e,f'!N3*'Results_e,f'!$L3/2+'Results_e,f'!P13*'Results_e,f'!$L13)/(('Results_e,f'!$L2/2)+('Results_e,f'!$L3/2)+'Results_e,f'!$L13) -> -26.764135
B17: 2 | C17: =('Results_e,f'!M3*'Results_e,f'!$L3/2+'Results_e,f'!M4*'Results_e,f'!$L4/2+'Results_e,f'!O14*'Results_e,f'!$L14)/(('Results_e,f'!$L3/2)+('Results_e,f'!$L4/2)+'Results_e,f'!$L14) -> -90.831377 | D17: =('Results_e,f'!N3*'Results_e,f'!$L3/2+'Results_e,f'!N4*'Results_e,f'!$L4/2+'Results_e,f'!P14*'Results_e,f'!$L14)/(('Results_e,f'!$L3/2)+('Results_e,f'!$L4/2)+'Results_e,f'!$L14) -> -29.886561
B18: 3 | C18: =('Results_e,f'!M4*'Results_e,f'!$L4/2+'Results_e,f'!M5*'Results_e,f'!$L5/2+'Results_e,f'!O15*'Results_e,f'!$L15)/(('Results_e,f'!$L4/2)+('Results_e,f'!$L5/2)+'Results_e,f'!$L15) -> -88.572137 | D18: =('Results_e,f'!N4*'Results_e,f'!$L4/2+'Results_e,f'!N5*'Results_e,f'!$L5/2+'Results_e,f'!P15*'Results_e,f'!$L15)/(('Results_e,f'!$L4/2)+('Results_e,f'!$L5/2)+'Results_e,f'!$L15) -> -29.143202
B19: 4 | C19: =('Results_e,f'!M5*'Results_e,f'!$L5/2+'Results_e,f'!M6*'Results_e,f'!$L6/2+'Results_e,f'!O16*'Results_e,f'!$L16)/(('Results_e,f'!$L5/2)+('Results_e,f'!$L6/2)+'Results_e,f'!$L16) -> -90.689335 | D19: =('Results_e,f'!N5*'Results_e,f'!$L5/2+'Results_e,f'!N6*'Results_e,f'!$L6/2+'Results_e,f'!P16*'Results_e,f'!$L16)/(('Results_e,f'!$L5/2)+('Results_e,f'!$L6/2)+'Results_e,f'!$L16) -> -29.839975
B20: 5 | C20: =('Results_e,f'!M6*'Results_e,f'!$L6/2+'Results_e,f'!M7*'Results_e,f'!$L7/2+'Results_e,f'!O17*'Results_e,f'!$L17)/(('Results_e,f'!$L6/2)+('Results_e,f'!$L7/2)+'Results_e,f'!$L17) -> -88.15962 | D20: =('Results_e,f'!N6*'Results_e,f'!$L6/2+'Results_e,f'!N7*'Results_e,f'!$L7/2+'Results_e,f'!P17*'Results_e,f'!$L17)/(('Results_e,f'!$L6/2)+('Results_e,f'!$L7/2)+'Results_e,f'!$L17) -> -29.007457
B21: 6 | C21: =('Results_e,f'!M7*'Results_e,f'!$L7/2+'Results_e,f'!M8*'Results_e,f'!$L8/2+'Results_e,f'!O18*'Results_e,f'!$L18)/(('Results_e,f'!$L7/2)+('Results_e,f'!$L8/2)+'Results_e,f'!$L18) -> -90.658606 | D21: =('Results_e,f'!N7*'Results_e,f'!$L7/2+'Results_e,f'!N8*'Results_e,f'!$L8/2+'Results_e,f'!P18*'Results_e,f'!$L18)/(('Results_e,f'!$L7/2)+('Results_e,f'!$L8/2)+'Results_e,f'!$L18) -> -29.829735
B22: 7 | C22: =('Results_e,f'!M8*'Results_e,f'!$L8/2+'Results_e,f'!M9*'Results_e,f'!$L9/2+'Results_e,f'!O19*'Results_e,f'!$L19)/(('Results_e,f'!$L8/2)+('Results_e,f'!$L9/2)+'Results_e,f'!$L19) -> -90.099817 | D22: =('Results_e,f'!N8*'Results_e,f'!$L8/2+'Results_e,f'!N9*'Results_e,f'!$L9/2+'Results_e,f'!P19*'Results_e,f'!$L19)/(('Results_e,f'!$L8/2)+('Results_e,f'!$L9/2)+'Results_e,f'!$L19) -> -29.645815
B23: 8 | C23: =('Results_e,f'!M9*'Results_e,f'!$L9/2+'Results_e,f'!M10*'Results_e,f'!$L10/2+'Results_e,f'!O20*'Results_e,f'!$L20)/(('Results_e,f'!$L9/2)+('Results_e,f'!$L10/2)+'Results_e,f'!$L20) -> -92.755483 | D23: =('Results_e,f'!N9*'Results_e,f'!$L9/2+'Results_e,f'!N10*'Results_e,f'!$L10/2+'Results_e,f'!P20*'Results_e,f'!$L20)/(('Results_e,f'!$L9/2)+('Results_e,f'!$L10/2)+'Results_e,f'!$L20) -> -30.519495
B24: 9 | C24: =('Results_e,f'!M10*'Results_e,f'!$L10/2+'Results_e,f'!M11*'Results_e,f'!$L11/2+'Results_e,f'!O21*'Results_e,f'!$L21)/(('Results_e,f'!$L10/2)+('Results_e,f'!$L11/2)+'Results_e,f'!$L21) -> -82.499216 | D24: =('Results_e,f'!N10*'Results_e,f'!$L10/2+'Results_e,f'!N11*'Results_e,f'!$L11/2+'Results_e,f'!P21*'Results_e,f'!$L21)/(('Results_e,f'!$L10/2)+('Results_e,f'!$L11/2)+'Results_e,f'!$L21) -> -27.144825
B27: linear Euler | C27: sigma_crip / cutoff | D27: lamda | E27: sigma_critical
B28: 1 | C28: =IF(COUNTIF(f_Crippling!$Y$2:$Y$6,$B3)>0,f_Crippling!$Q$18,IF(COUNTIF(f_Crippling!$AA$2:$AA$6,$B3)>0,f_Crippling!$T$18,NA())) -> 394.86591 | D28: =IF(COUNTIF(f_Crippling!$Y$2:$Y$6,$B3)>0,f_Crippling!$Q$16,IF(COUNTIF(f_Crippling!$AA$2:$AA$6,$B3)>0,f_Crippling!$T$16,NA())) -> 82.40927 | E28: =(PI()^2*f_Crippling!$H$3)/(f_RF!D28^2) -> 95.398219
B29: 2 | C29: =IF(COUNTIF(f_Crippling!$Y$2:$Y$6,$B4)>0,f_Crippling!$Q$18,IF(COUNTIF(f_Crippling!$AA$2:$AA$6,$B4)>0,f_Crippling!$T$18,NA())) -> 394.86591 | D29: =IF(COUNTIF(f_Crippling!$Y$2:$Y$6,$B4)>0,f_Crippling!$Q$16,IF(COUNTIF(f_Crippling!$AA$2:$AA$6,$B4)>0,f_Crippling!$T$16,NA())) -> 82.40927 | E29: =(PI()^2*f_Crippling!$H$3)/(f_RF!D29^2) -> 95.398219
